<?xml version="1.0"?>
<robot name="threeseg">
  <link name="base_link" />
  <link name="link_1">
    <visual>
      <origin xyz="0 0 1.5" rpy="0 0 0"/>
      <geometry>
        <box size="0.1 0.1 3"/>
      </geometry>
    </visual>
  </link>
  <link name="link_2">
    <visual>
      <origin xyz="0 0 1" rpy="0 0 0"/>
      <geometry>
        <box size="0.1 0.1 2"/>
      </geometry>
    </visual>
  </link>
  <link name="link_3">
    <visual>
      <origin xyz="0 0 0.5" rpy="0 0 0"/>
      <geometry>
        <box size="0.1 0.1 1"/>
      </geometry>
    </visual>
  </link>
  <link name="tool0"></link>

  <joint name="joint_1" type="revolute">
    <parent link="base_link" />
    <child link="link_1" />
    <limit effort="30" velocity="1.0" lower="-1.570795" upper="1.570795" />
    <origin xyz="0 0 0" rpy="0 0 0" />
    <axis xyz="0 0 1" />
  </joint>
  <joint name="joint_2" type="revolute">
    <parent link="link_1" />
    <child link="link_2" />
    <limit effort="30" velocity="1.0" lower="-1.570795" upper="1.570795" />
    <origin xyz="0 0 3" rpy="-0.785398 0 0" />
    <axis xyz="1 0 0" />
  </joint>
  <joint name="joint_3" type="revolute">
    <parent link="link_2" />
    <child link="link_3" />
    <limit effort="30" velocity="1.0" lower="-1.570795" upper="1.570795" />
    <origin xyz="0 0 2" rpy="-0.5 0 0" />
    <axis xyz="1 0 0" />
  </joint>
  <joint name="joint_4-tool0" type="revolute">
    <parent link="link_3" />
    <child link="tool0" />
    <limit effort="30" velocity="1.0" lower="-6.28318" upper="6.28318" />
    <origin xyz="0 0 1" rpy="0 0 0" />
    <axis xyz="0 0 1" />
  </joint>
</robot>
