<?xml version="1.0" ?>
<!-- =================================================================================== -->
<!-- |    This document was autogenerated by xacro from al5d.xacro                     | -->
<!-- |    EDITING THIS FILE BY HAND IS NOT RECOMMENDED                                 | -->
<!-- =================================================================================== -->
<robot name="lynxmotion_al5d" xmlns:xacro="http://ros.org/wiki/xacro">
  <!-- attach -->
  <!-- links -->
  <link name="base_link">
    <visual>
      <origin rpy="0 0 0" xyz="0 -0.015 0.0015"/>
      <geometry>
        <mesh filename="package://lynxmotion_al5d_support/meshes/base_1.dae"/>
      </geometry>
      <material name="black">
        <color rgba="0 0 0 1"/>
      </material>
    </visual>
    <collision>
      <origin rpy="0 0 0" xyz="0 0 0.015"/>
      <geometry>
        <cylinder length="0.043" radius="0.048"/>
      </geometry>
    </collision>
  </link>
  <link name="link_1">
    <visual>
      <origin rpy="0 0 0" xyz="0.0 -0.018 -0.042"/>
      <geometry>
        <mesh filename="package://lynxmotion_al5d_support/meshes/link_11.dae"/>
      </geometry>
      <material name="black">
        <color rgba="0 0 0 1"/>
      </material>
    </visual>
    <collision>
      <origin rpy="0 0 0" xyz="0 0 0"/>
      <geometry>
        <cylinder length="0.006" radius="0.048"/>
      </geometry>
    </collision>
  </link>
  <link name="link_2">
    <visual>
      <origin rpy="-0.38 0 0" xyz="0 -0.035 -0.06"/>
      <geometry>
        <mesh filename="package://lynxmotion_al5d_support/meshes/link_2.dae"/>
      </geometry>
      <material name="silver">
        <color rgba="0.8 0.8 0.8 1"/>
      </material>
    </visual>
    <collision>
      <origin rpy="0.1 0 0" xyz="0.073025 0 0"/>
      <geometry>
        <box size="0.12605 0.02 .02"/>
      </geometry>
    </collision>
  </link>
  <link name="link_3">
    <visual>
      <origin rpy="0 -1.570795 0" xyz="0.23 0.02 0.0"/>
      <geometry>
        <mesh filename="package://lynxmotion_al5d_support/meshes/link_3.dae"/>
      </geometry>
      <material name="silver">
        <color rgba="0.8 0.8 0.8 1"/>
      </material>
    </visual>
    <collision>
      <origin rpy="0 0 0" xyz="0.0936625 0 0"/>
      <geometry>
        <box size="0.187325 0.02 0.02"/>
      </geometry>
    </collision>
  </link>
  <link name="link_4">
    <visual>
      <origin rpy="0 0 0" xyz="0.09 0 0"/>
      <geometry>
        <box size="0.032 0.02 0.02"/>
      </geometry>
      <material name="black">
        <color rgba="0 0 0 1"/>
      </material>
    </visual>
    <collision>
      <origin rpy="0 0 0" xyz="0.0 0 0"/>
      <geometry>
        <box size="0.032 0.02 0.02"/>
      </geometry>
    </collision>
  </link>
  <link name="gripper">
    <visual>
      <origin rpy="0 0 0" xyz="0.0 0.17 -0.06"/>
      <geometry>
        <mesh filename="package://lynxmotion_al5d_support/meshes/gripper.dae"/>
      </geometry>
      <material name="black">
        <color rgba="0 0 0 1"/>
      </material>
    </visual>
    <collision>
      <origin rpy="0 0 0" xyz="0 0 0.5"/>
      <geometry>
        <box size="0.05 0.05 0.05"/>
      </geometry>
    </collision>
  </link>
  <link name="tool0"/>

  <!-- joints -->
  <joint name="joint_1" type="revolute">
    <origin rpy="0 0 0" xyz="0 0 0.045"/>
    <parent link="base_link"/>
    <child link="link_1"/>
    <axis xyz="0 0 1"/>
    <limit effort="0" lower="-1.570795" upper="1.570795" velocity="3.67"/>
  </joint>
  <joint name="joint_2" type="revolute">
    <origin rpy="0 0 0" xyz="0 -0.01 0.028"/>
    <parent link="link_1"/>
    <child link="link_2"/>
    <axis xyz="1 0 0"/>
    <limit effort="0" lower="-1.570795" upper="1.570795" velocity="3.32"/>
  </joint>
  <joint name="joint_3" type="revolute">
    <origin rpy="0 -1.57 0" xyz="0 0 0.15"/>
    <parent link="link_2"/>
    <child link="link_3"/>
    <axis xyz="0 0 1"/>
    <limit effort="0" lower="-1.570795" upper="1.570795" velocity="3.67"/>
  </joint>
  <joint name="joint_4" type="revolute">
    <origin rpy="0 1.57 0" xyz="0.17 -0.15 0.03"/>
    <parent link="link_3"/>
    <child link="link_4"/>
    <axis xyz="1 0 0"/>
    <limit effort="0" lower="-1.570795" upper="1.570795" velocity="6.98"/>
  </joint>
  <joint name="gripper" type="fixed">
    <origin rpy="0 0 0" xyz="0.048 0 0"/>
    <parent link="link_4"/>
    <child link="gripper"/>
    <axis xyz="0 0 1"/>
    <limit effort="0" lower="-1.570795" upper="1.570795" velocity="6.98"/>
  </joint>

    <joint name="joint3-tool0" type="fixed">
      <parent link="gripper"/>
      <child link="tool0"/>
      <origin rpy="0 0 0" xyz="0 0 0"/>
    </joint>

>
</robot>

