<?xml version="1.0"?>
<robot name="Cylindrical">

 <link name="base_link">

    <visual>
        <origin xyz="0 0 0.05 " rpy="0 0 0" />
        <geometry>
          <box size="1.0 1.0 0.1" />
        </geometry>
        <material name="red">
        <color rgba="0.8 0.0 0.0 1.0"/>
        </material>
    </visual>

 <visual>
        <origin xyz="0 0 0.14 " rpy="0 0 0" />
        <geometry>
    <cylinder length="0.05" radius="0.3"/>
        </geometry>
  <material name="SickBlue">
    <color rgba="0.3058 0.5921 0.7294 1.0"/>
  </material>
    </visual>


  </link>


<link name="link_1">

   <visual>
        <origin xyz="0 0 0.6 " rpy="0 0 0" />
        <geometry>
    <cylinder length="1" radius="0.05"/>
        </geometry>
  <material name="HandGray">
    <color rgba="0.953 0.996 0.694 1.0"/>
  </material>
    </visual>

  </link>

 <joint name="joint_1" type="revolute">
    <axis xyz="0 0 1"/>
    <limit effort="306" lower="-3.14159" upper="3.14159" velocity="0.5"/>
    <origin rpy="0 0 0" xyz="0 0 0"/>
    <parent link="base_link"/>
    <child link="link_1"/>
  </joint>

</robot>