<?xml version="1.0" ?>
<!-- =================================================================================== -->
<!-- |    This document was autogenerated by xacro from katana_450_6m90a.urdf.xacro    | -->
<!-- |    EDITING THIS FILE BY HAND IS NOT RECOMMENDED                                 | -->
<!-- =================================================================================== -->
<robot name="katana_450_6m90a" xmlns:xacro="http://ros.org/wiki/xacro">
  <!-- transmissions are required by the controller manager (here: for simulation in gazebo) -->
  <link name="base_link">
    <visual>
      <origin rpy="0 0 0" xyz="0 0 0"/>
      <geometry>
        <mesh filename="package://rvizglabre/modelos/katana/katana_base_link.stl"/>
      </geometry>
      <material name="grey">
        <color rgba="0.8 0.8 0.8 1"/>
      </material>
    </visual>
  </link>
  <joint name="joint_1" type="revolute">
    <!-- Joint 1 in Katana Manual -->
    <parent link="base_link"/>
    <child link="link_1"/>
    <origin rpy="0 0 0" xyz="0 0 0.2015"/>
    <axis xyz="0 0 1"/>
    <limit effort="1.5" lower="-3.025528" upper="2.891097" velocity="2.208932"/>
  </joint>
  <link name="link_1">
    <visual>
      <origin rpy="0 0 0" xyz="0 0 -0.2015"/>
      <geometry>
        <mesh filename="package://rvizglabre/modelos/katana/katana_motor1_pan_link.stl"/>
      </geometry>
      <material name="grey"/>
    </visual>
  </link>
  <joint name="joint_2" type="revolute">
    <!-- Joint 2 in Katana Manual -->
    <parent link="link_1"/>
    <child link="link_2"/>
    <origin rpy="1.57079632679 0 0" xyz="0 0 0"/>
    <axis xyz="0 0 1"/>
    <limit effort="0.6" lower="-0.135228" upper="2.168572" velocity="1.190799"/>
  </joint>
  <link name="link_2">
    <visual>
      <origin rpy="-1.57079632679 0 0" xyz="0 0 0"/>
      <geometry>
        <mesh filename="package://rvizglabre/modelos/katana/katana_motor2_lift_link.stl"/>
      </geometry>
      <!-- <geometry>
          <cylinder length="${link2_length}" radius="0.02"/>
        </geometry>
        <origin rpy="0 ${-M_PI/2} 0" xyz="${link2_length/2} 0 0" /> -->
      <material name="grey"/>
    </visual>
  </link>
  <joint name="joint_3" type="revolute">
    <!-- Joint 3 in Katana Manual -->
    <parent link="link_2"/>
    <child link="link_3"/>
    <origin rpy="0 0 0" xyz="0.19 0 0"/>
    <axis xyz="0 0 1"/>
    <!-- unexplicably, the measured velocity limit of this motor is exactly half of what vel_enc2rad(180) says -->
    <limit effort="0.25" lower="-2.221804" upper="2.054223" velocity="1.190799"/>
  </joint>
  <link name="link_3">
    <visual>
      <origin rpy="-1.57079632679 0 0" xyz="0 0 0"/>
      <geometry>
        <mesh filename="package://rvizglabre/modelos/katana/katana_motor3_lift_link.stl"/>
      </geometry>
      <!--<geometry>
          <cylinder length="${link3_length}" radius="0.02"/>
        </geometry>
        <origin rpy="0 ${-M_PI/2} 0" xyz="${link3_length/2} 0 0" />-->
      <material name="grey"/>
    </visual>
  </link>
  <joint name="joint_4" type="revolute">
    <!-- Joint 4 in Katana Manual -->
    <parent link="link_3"/>
    <child link="link_4"/>
    <origin rpy="3.14159265359 0 0" xyz="0.139 0 0"/>
    <axis xyz="0 0 1"/>
    <limit effort="0.1" lower="-2.033309" upper="1.876133" velocity="2.208932"/>
  </joint>
  <link name="link_4">
    <visual>
      <origin rpy="1.57079632679 0 0" xyz="0 0 0"/>
      <geometry>
        <mesh filename="package://rvizglabre/modelos/katana/katana_motor4_lift_link.stl"/>
      </geometry>
      <!-- <geometry>
          <cylinder length="${link4_length}" radius="0.02"/>
        </geometry>
        <origin rpy="0 ${-M_PI/2} 0" xyz="${link4_length/2} 0 0" /> -->
      <material name="grey"/>
    </visual>
  </link>
  <joint name="joint_5" type="revolute">
    <!-- Joint 5 in Katana Manual -->
    <parent link="link_4"/>
    <child link="link_5"/>
    <origin rpy="1.57079632679 0 -1.57079632679" xyz="0.1473 0 0"/>
    <axis xyz="0 0 1"/>
    <limit effort="0.01" lower="-2.993240" upper="2.870985" velocity="2.208932"/>
  </joint>
  <link name="link_5">
    <visual>
      <origin rpy="0 1.57079632679 0" xyz="0 0 0"/>
      <geometry>
        <mesh filename="package://rvizglabre/modelos/katana/katana_motor5_wrist_roll_link.stl"/>
      </geometry>
      <!--<geometry>
          <cylinder length="${link5_length}" radius="0.02"/>
        </geometry>
        <origin rpy="0 ${-M_PI/2} 0" xyz="${link5_length/2} 0 0" />-->
      <material name="grey"/>
    </visual>
  </link>
  <joint name="joint_6" type="fixed">
    <parent link="link_5"/> 
    <child link="tool0"/>
    <origin rpy="0 0 0" xyz="0.0323 0 0"/>
  </joint>
  <link name="tool0">
    <visual>
      <origin rpy="0 3.14159265359 0" xyz="0 0 0"/>
      <geometry>
        <mesh filename="package://rvizglabre/modelos/katana/katana_gripper_link.stl"/>
      </geometry>
      <material name="grey"/>
    </visual>
  </link>
  <joint name="katana_r_finger_joint" type="revolute">
    <parent link="tool0"/>
    <child link="katana_r_finger_link"/>
    <origin rpy="0 0 0" xyz="0.034 0 0"/>
    <axis xyz="0 0 1"/>
    <limit effort="0.5" lower="-0.44" upper="0.30" velocity="0.718834"/>
  </joint>
  <link name="katana_r_finger_link">
    <visual>
      <origin rpy="0 3.14159265359 0" xyz="0 0 0"/>
      <geometry>
        <mesh filename="package://rvizglabre/modelos/katana/katana_gripper_r_finger.stl"/>
      </geometry>
      <material name="grey"/>
    </visual>
  </link>
  <joint name="katana_l_finger_joint" type="revolute">
    <parent link="tool0"/>
    <child link="katana_l_finger_link"/>
    <origin rpy="3.14159265359 0 0" xyz="0.034 0 0"/>
    <axis xyz="0 0 1"/>
    <limit effort="0.5" lower="-0.44" upper="0.30" velocity="0.718834"/>
  </joint>
  <link name="katana_l_finger_link">
    <visual>
      <origin rpy="0 3.14159265359 0" xyz="0 0 0"/>
      <geometry>
        <mesh filename="package://rvizglabre/modelos/katana/katana_gripper_l_finger.stl"/>
      </geometry>
      <material name="grey"/>
    </visual>
  </link>
  <joint name="katana_gripper_tool_frame_joint" type="fixed">
    <parent link="link_5"/>
    <child link="katana_gripper_tool_frame"/>
    <origin rpy="0 1.57079632679 0" xyz="0.11 0 0"/>
  </joint>
  <link name="katana_gripper_tool_frame">
    <!-- This is the coordinate system of the end effector (this is the position
         used in IK); there is no actual arm part attached to this link -->
    <!-- The fake geometry here is only present to work around https://github.com/ros-planning/moveit_core/issues/158 -->
    <visual>
      <origin rpy="0 0 0" xyz="0 0 -0.11"/>
      <geometry>
        <box size="0.01 0.01 0.01"/>
      </geometry>
      <material name="grey"/>
    </visual>
    <collision>
      <origin rpy="0 0 0" xyz="0 0 -0.11"/>
      <geometry>
        <box size="0.01 0.01 0.01"/>
      </geometry>
      <material name="grey"/>
    </collision>
  </link>
</robot>

