<?xml version="1.0" ?>
<!-- =================================================================================== -->
<!-- |    This document was autogenerated by xacro from kr210l150.xacro                | -->
<!-- |    EDITING THIS FILE BY HAND IS NOT RECOMMENDED                                 | -->
<!-- =================================================================================== -->
<!--Generates a urdf from the macro in kr210_macro.xacro -->
<robot name="kuka_kr210" xmlns:xacro="http://wiki.ros.org/xacro">
  <link name="base_link">
    <visual>
      <origin rpy="-1.570796327 0 0" xyz="0 0 0"/>
      <geometry>
        <mesh filename="package://rvizglabre/modelos/kr210l150/visual/base_link.dae"/>
      </geometry>
      <material name="">
        <color rgba="0.75294 0.75294 0.75294 1"/>
      </material>
    </visual>
    <collision>
      <origin rpy="-1.570796327 0 0" xyz="0 0 0"/>
      <geometry>
        <mesh filename="package://rvizglabre/modelos/kr210l150/collision/base_link.stl"/>
      </geometry>
    </collision>
  </link>
  <link name="link_1">
    <visual>
      <origin rpy="0 0 0" xyz="0 0 0"/>
      <geometry>
        <mesh filename="package://rvizglabre/modelos/kr210l150/visual/link_1.dae"/>
      </geometry>
      <material name="">
        <color rgba="0.75294 0.75294 0.75294 1"/>
      </material>
    </visual>
    <collision>
      <origin rpy="0 0 0" xyz="0 0 0"/>
      <geometry>
        <mesh filename="package://rvizglabre/modelos/kr210l150/collision/link_1.stl"/>
      </geometry>
    </collision>
  </link>
  <link name="link_2">
    <visual>
      <origin rpy="-1.570796327 0 0" xyz="0 0 0"/>
      <geometry>
        <mesh filename="package://rvizglabre/modelos/kr210l150/visual/link_2.dae"/>
      </geometry>
      <material name="">
        <color rgba="0.75294 0.75294 0.75294 1"/>
      </material>
    </visual>
    <collision>
      <origin rpy="0 0 0" xyz="0 0 0"/>
      <geometry>
        <mesh filename="package://rvizglabre/modelos/kr210l150/collision/link_2.stl"/>
      </geometry>
    </collision>
  </link>
  <link name="link_3">
    <visual>
      <origin rpy="-1.570796327 0 0" xyz="0 0 0"/>
      <geometry>
        <mesh filename="package://rvizglabre/modelos/kr210l150/visual/link_3.dae"/>
      </geometry>
      <material name="">
        <color rgba="0.75294 0.75294 0.75294 1"/>
      </material>
    </visual>
    <collision>
      <origin rpy="0 0 0" xyz="0 0 0"/>
      <geometry>
        <mesh filename="package://rvizglabre/modelos/kr210l150/collision/link_3.stl"/>
      </geometry>
    </collision>
  </link>
  <link name="link_4">
    <visual>
      <origin rpy="-1.570796327 0 0" xyz="0 0 0"/>
      <geometry>
        <mesh filename="package://rvizglabre/modelos/kr210l150/visual/link_4.dae"/>
      </geometry>
      <material name="">
        <color rgba="0.75294 0.75294 0.75294 1"/>
      </material>
    </visual>
    <collision>
      <origin rpy="0 0 0" xyz="0 0 0"/>
      <geometry>
        <mesh filename="package://rvizglabre/modelos/kr210l150/collision/link_4.stl"/>
      </geometry>
    </collision>
  </link>
  <link name="link_5">
    <visual>
      <origin rpy="-1.570796327 0 0" xyz="0 0 0"/>
      <geometry>
        <mesh filename="package://rvizglabre/modelos/kr210l150/visual/link_5.dae"/>
      </geometry>
      <material name="">
        <color rgba="0.75294 0.75294 0.75294 1"/>
      </material>
    </visual>
    <collision>
      <origin rpy="0 0 0" xyz="0 0 0"/>
      <geometry>
        <mesh filename="package://rvizglabre/modelos/kr210l150/collision/link_5.stl"/>
      </geometry>
    </collision>
  </link>
  <link name="link_6">
    <visual>
      <origin rpy="0 0 0" xyz="0 0 0"/>
      <geometry>
        <mesh filename="package://rvizglabre/modelos/kr210l150/visual/link_6.dae"/>
      </geometry>
      <material name="">
        <color rgba="0.75294 0.75294 0.75294 1"/>
      </material>
    </visual>
    <collision>
      <origin rpy="0 0 0" xyz="0 0 0"/>
      <geometry>
        <mesh filename="package://rvizglabre/modelos/kr210l150/collision/link_6.stl"/>
      </geometry>
    </collision>
  </link>
  <link name="tool0"/>
  <joint name="joint_1" type="revolute">
    <origin rpy="0 0 0" xyz="-0.00262 0.00097586 0.33099"/>
    <parent link="base_link"/>
    <child link="link_1"/>
    <axis xyz="0 0 1"/>
    <limit effort="0" lower="-3.228859205" upper="3.228859205" velocity="2.146755039"/>
  </joint>
  <joint name="joint_2" type="revolute">
    <origin rpy="0 0 0" xyz="0.35277 -0.037476 0.4192"/>
    <parent link="link_1"/>
    <child link="link_2"/>
    <axis xyz="0 1 0"/>
    <limit effort="0" lower="-0.785398185" upper="1.483529905" velocity="2.007128695"/>
  </joint>
  <joint name="joint_3" type="revolute">
    <origin rpy="0 0 0" xyz="-9.8483E-05 -0.1475 1.2499"/>
    <parent link="link_2"/>
    <child link="link_3"/>
    <axis xyz="0 1 0"/>
    <limit effort="0" lower="-3.66519153" upper="1.134464045" velocity="1.954768816"/>
  </joint>
  <joint name="joint_4" type="revolute">
    <origin rpy="0 0 0" xyz="0.95795 0.184 -0.055059"/>
    <parent link="link_3"/>
    <child link="link_4"/>
    <axis xyz="1 0 0"/>
    <limit effort="0" lower="-6.10865255" upper="6.10865255" velocity="3.124139447"/>
  </joint>
  <joint name="joint_5" type="revolute">
    <origin rpy="0 0 0" xyz="0.542 0 0"/>
    <parent link="link_4"/>
    <child link="link_5"/>
    <axis xyz="0 1 0"/>
    <limit effort="0" lower="-2.181661625" upper="2.181661625" velocity="3.001966396"/>
  </joint>
  <joint name="joint_6" type="revolute">
    <origin rpy="0 0 0" xyz="0.1925 0 0"/>
    <parent link="link_5"/>
    <child link="link_6"/>
    <axis xyz="1 0 0"/>
    <limit effort="0" lower="-6.10865255" upper="6.10865255" velocity="3.822271167"/>
  </joint>
  <joint name="link_6-tool0" type="fixed">
    <parent link="link_6"/>
    <child link="tool0"/>
    <origin rpy="0 0 0" xyz="0.0375 0 -0.00023924"/>
  </joint>
  <link name="Link1"/>
  <joint name="Link1-link_1" type="fixed">
    <parent link="link_1"/>
    <child link="Link1"/>
    <origin rpy="0 0 0" xyz="0 0 0"/>
  </joint>
</robot>
