<?xml version="1.0" ?>
<robot name="urdf_robot">

  <link name="base_link">
    <visual>
      <origin rpy="0 0 0" xyz="0 0 0.25"/>
      <geometry>
      <box size="0.3 0.3 0.5"/>
      </geometry>
    </visual>
    <collision>
      <origin rpy="0 0 0" xyz="0 0 0.25"/>
      <geometry>
         <box size="0.3 0.3 0.5"/>
      </geometry>
    </collision>
  </link>

   <link name="link_1">
    <visual>
      <origin rpy="0 0 0" xyz="0 0 0.5"/>
      <geometry>
        <box size="0.2 .2 1"/>
      </geometry>
    </visual>
    <collision>
      <origin rpy="0 0 0" xyz="0 0 0.5"/>
      <geometry>
        <box size="0.2 .2 1"/>
      </geometry>
    </collision>
  </link>

  <link name="tool0"/>

   <joint name="joint_1" type="prismatic">
    <parent link="base_link"/>
    <child link="link_1"/>
    <origin xyz="0 0 0"/>
        <axis xyz="0 0 1"/>
        <limit effort="1000.0" lower="-0.5" upper="0.5" velocity="0.5"/>
  </joint>

<joint name="joint_2" type="revolute">
  <parent link="link_1"/>
  <child link="tool0"/>
  <limit effort="30" velocity="1.0" lower="-0.1" upper="0.1" />
  <origin xyz="0 0 1" rpy="0 0 0" />
  <axis xyz="0 0 1" />
</joint>
 
</robot>
