<?xml version="1.0" ?>
<!-- =================================================================================== -->
<!-- |    This document was autogenerated by xacro from puma560.xacro                  | -->
<!-- |    EDITING THIS FILE BY HAND IS NOT RECOMMENDED                                 | -->
<!-- =================================================================================== -->
<!-- UNIMATE Puma 560 Manipulator -->
<robot name="puma560">

  <material name="blue">
    <color rgba="0.0 0.0 0.8 1.0"/>
  </material>
  <material name="green">
    <color rgba="0.0 0.8 0.0 1.0"/>
  </material>

  <material name="red">
    <color rgba="0.8 0.0 0.0 1.0"/>
  </material>
  <material name="red_transparent">
    <color rgba="0.8 0.0 0.0 0.5"/>
  </material>
  <material name="white">
    <color rgba="1.0 1.0 1.0 1.0"/>
  </material>

  <material name="brown">
    <color rgba="0.870588235294 0.811764705882 0.764705882353 1.0"/>
  </material>

  <material name="wood">
    <color rgba="0.803921568627 0.521568627451 0.247058823529 1.0"/>
  </material>
  <!-- Link definitions -->
  <link name="base_link">
    <visual>
      <origin rpy="0 0 0" xyz="0 0 0.54864"/>
      <geometry>
        <mesh filename="package://rvizglabre/modelos/puma560/puma_base.stl"/>
      </geometry>
       <material name="grey">
         <color rgba="0.2 0.2 0.2 1.0"/>
       </material>
    </visual>
    <collision>
      <origin rpy="0 0 0" xyz="0 0 0"/>
      <geometry>
        <mesh filename="package://rvizglabre/modelos/puma560/puma_base_collision.stl"/>
      </geometry>
    </collision>
  </link>
  <joint name="joint_1" type="revolute">
    <parent link="base_link"/>
    <child link="link_1"/>
    <origin rpy="0 0 0" xyz="0 0 0.62357"/>
    <axis xyz="0 0 1"/>
    <limit effort="1000.0" lower="-3.14159265" upper="3.14159265" velocity="0"/>
  </joint>
  <link name="link_1">
    <visual>
      <origin rpy="0 0 0" xyz="0 0 0"/>
      <geometry>
        <mesh filename="package://rvizglabre/modelos/puma560/puma_link_1.stl"/>
      </geometry>
  <material name="metal">
    <color rgba="0.827450980392 0.827450980392 0.827450980392 1.0"/>
  </material>
    </visual>
    <collision>
      <origin rpy="0 0 0" xyz="0 0 0"/>
      <geometry>
        <mesh filename="package://rvizglabre/modelos/puma560/puma_link_1_collision.stl"/>
      </geometry>
    </collision>
  </link>
  <joint name="joint_2" type="revolute">
    <parent link="link_1"/>
    <child link="link_2"/>
    <origin rpy="1.57079632679 0 0" xyz="0 0.16764 0"/>
    <axis xyz="0 0 1"/>
    <limit effort="1000.0" lower="-1.570796325" upper="1.570796325" velocity="0"/>
  </joint>
  <link name="link_2">
    <visual>
      <origin rpy="0 0 0" xyz="0 0 0"/>
      <geometry>
        <mesh filename="package://rvizglabre/modelos/puma560/puma_link_2.stl"/>
      </geometry>
  <material name="metal">
    <color rgba="0.827450980392 0.827450980392 0.827450980392 1.0"/>
  </material>
    </visual>
    <collision>
      <origin rpy="0 0 0" xyz="0 0 0"/>
      <geometry>
        <mesh filename="package://rvizglabre/modelos/puma560/puma_link_2_collision.stl"/>
      </geometry>
    </collision>
  </link>
  <joint name="joint_3" type="revolute">
    <parent link="link_2"/>
    <child link="link_3"/>
    <origin rpy="0 0 0" xyz="0.4318 0 0"/>
    <axis xyz="0 0 1"/>
    <limit effort="1000.0" lower="-1.570796325" upper="1.570796325" velocity="0"/>
  </joint>
  <link name="link_3">
    <visual>
      <origin rpy="0 0 0" xyz="0 0 0"/>
      <geometry>
        <mesh filename="package://rvizglabre/modelos/puma560/puma_link_3.stl"/>
      </geometry>
  <material name="metal">
    <color rgba="0.827450980392 0.827450980392 0.827450980392 1.0"/>
  </material>
    </visual>
    <collision>
      <origin rpy="0 0 0" xyz="0 0 0"/>
      <geometry>
        <mesh filename="package://rvizglabre/modelos/puma560/puma_link_3_collision.stl"/>
      </geometry>
    </collision>
  </link>
  <joint name="joint_4" type="revolute">
    <parent link="link_3"/>
    <child link="link_4"/>
    <origin rpy="0 1.57079632679 0" xyz="0.35179 0 0.0381 "/>
    <axis xyz="0 0 1"/>
    <limit effort="1000.0" lower="-1.570796325" upper="1.570796325" velocity="0"/>
  </joint>
  <link name="link_4">
    <visual>
      <origin rpy="0 0 0" xyz="0 0 0"/>
      <geometry>
        <mesh filename="package://rvizglabre/modelos/puma560/puma_link_4.stl"/>
      </geometry>
  <material name="orange">
    <color rgba="1.0 0.423529411765 0.0392156862745 1.0"/>
  </material>
    </visual>
    <collision>
      <origin rpy="0 0 0" xyz="0 0 0"/>
      <geometry>
        <mesh filename="package://rvizglabre/modelos/puma560/puma_link_4_collision.stl"/>
      </geometry>
    </collision>
  </link>
  <joint name="joint_5" type="revolute">
    <parent link="link_4"/>
    <child link="link_5"/>
    <origin rpy="0 -1.57079632679 -1.57079632679" xyz="0 0 0.0803 "/>
    <axis xyz="0 0 1"/>
    <limit effort="1000.0" lower="-1.570796325" upper="1.570796325" velocity="0"/>
  </joint>
  <link name="link_5">
    <visual>
      <origin rpy="0 0 0" xyz="0 0 0"/>
      <geometry>
        <mesh filename="package://rvizglabre/modelos/puma560/puma_link_5.stl"/>
      </geometry>
  <material name="orange">
    <color rgba="1.0 0.423529411765 0.0392156862745 1.0"/>
  </material>
    </visual>
    <collision>
      <origin rpy="0 0 0" xyz="0 0 0"/>
      <geometry>
        <mesh filename="package://rvizglabre/modelos/puma560/puma_link_5_collision.stl"/>
      </geometry>
    </collision>
  </link>
  <joint name="joint5-tool0" type="fixed">
    <parent link="link_5"/>
    <child link="tool0"/>
    <origin rpy="0 0 0" xyz="0 0 0"/>
  </joint>
  <link name="tool0"/>
</robot>
  <link name="base"/>
  <joint name="base_link-base" type="fixed">
    <origin rpy="0 0 0" xyz="0 0 0"/>
    <parent link="base"/>
    <child link="base_link"/>
  </joint>
