<?xml version="1.0"?>

<robot name="origins">
	<link name="base_link">
   		<visual>
     			<geometry>
       				<box size="0.2 .3 .1"/>
     			</geometry>
                        <origin rpy="0 0 0" xyz="0 0 0.05"/>
			<material name="white">
				<color rgba="1 1 1 1"/>
			</material>
   		</visual>
		<collision>
			<geometry>
       				<box size="0.2 .3 0.1"/>
			</geometry>
		</collision>
				
 	</link>


	<link name="link_1">
   		<visual>
     			<geometry>
       				<box size="0.05 .05 0.5"/>
     			</geometry>
                        <origin rpy="0 0 0" xyz="0 0 0.25"/>
			<material name="white">
				<color rgba="1 1 1 1"/>
			</material>
   		</visual>
		<collision>
			<geometry>
       				<box size="0.05 .05 0.5"/>
			</geometry>
		</collision>

 	</link>
        <link name="link_2">
                <visual>
                        <geometry>
                                <box size="0.05 .05 0.5"/>
                        </geometry>
                        <origin rpy="0 0 0" xyz="0.06 0 0.15"/>
                        <material name="white">
                                <color rgba="1 1 1 1"/>
                        </material>
                </visual>
                <collision>
                        <geometry>
                                <box size="0.05 .05 0.5"/>
                        </geometry>
                </collision>

        </link>
  <link name="tool0"></link>



	<joint name="joint_1" type="revolute">
                <parent link="base_link"/>
		<child link="link_1"/>
                <axis xyz="1 0 0"/>
                <origin xyz="0 0 0.15"/>
                <limit effort ="0" lower="-1.0" upper="1.0" velocity="0.5"/>
	</joint>


	<joint name="joint_2" type="revolute">
		<parent link="link_1"/>
		<child link="link_2"/>
                <axis xyz="1 0 0"/>
                <origin xyz="0 0 0.45"/>
                <limit effort ="0" lower="-2.5" upper="2.5" velocity="0.5"/>
	</joint>

  <joint name="joint_3" type="revolute">
    <parent link="link_2"/>
    <child link="tool0"/>
    <origin rpy="0 -1.57 0" xyz="0.06 0 0.4"/>
    <limit effort ="0" lower="-0.1" upper="0.1" velocity="0.5"/>

  </joint>



     	

</robot>
