<?xml version="1.0" ?>
<!-- =================================================================================== -->
<!-- |    This document was autogenerated by xacro from sia10f.xacro                   | -->
<!-- |    EDITING THIS FILE BY HAND IS NOT RECOMMENDED                                 | -->
<!-- =================================================================================== -->
<robot name="motoman_sia10f" xmlns:xacro="http://ros.org/wiki/xacro">
  <link name="base_link">
    <visual>
      <geometry>
        <mesh filename="package://rvizglabre/modelos/sia10f/visual/motoman_base.stl"/>
      </geometry>
      <material name="blue">
        <color rgba="0 0 1 1"/>
      </material>
    </visual>
    <collision>
      <geometry>
        <mesh filename="package://rvizglabre/modelos/sia10f/collision/motoman_base.stl"/>
      </geometry>
      <material name="yellow">
        <color rgba="0 1 1 1"/>
      </material>
    </collision>
  </link>
  <link name="link_1">
    <visual>
      <geometry>
        <mesh filename="package://rvizglabre/modelos/sia10f/visual/motoman_axis_s.stl"/>
      </geometry>
      <material name="silver">
        <color rgba="0.8 0.8 0.8 1"/>
      </material>
    </visual>
    <collision>
      <geometry>
        <mesh filename="package://rvizglabre/modelos/sia10f/collision/motoman_axis_s.stl"/>
      </geometry>
      <material name="yellow"/>
    </collision>
  </link>
  <link name="link_2">
    <visual>
      <origin rpy="1.57 3.1416 0" xyz="0 0 0"/>
      <geometry>
        <mesh filename="package://rvizglabre/modelos/sia10f/visual/motoman_axis_l.stl"/>
      </geometry>
      <material name="blue"/>
    </visual>
    <collision>
      <origin rpy="1.57 3.1416 0" xyz="0 0 0"/>
      <geometry>
        <mesh filename="package://rvizglabre/modelos/sia10f/collision/motoman_axis_l.stl"/>
      </geometry>
      <material name="yellow"/>
    </collision>
  </link>
  <link name="link_3">
    <visual>
      <origin rpy="0 0 3.1415" xyz="0 0 0"/>
      <geometry>
        <mesh filename="package://rvizglabre/modelos/sia10f/visual/motoman_axis_e.stl"/>
      </geometry>
      <material name="silver"/>
    </visual>
    <collision>
      <origin rpy="0 0 3.1415" xyz="0 0 0"/>
      <geometry>
        <mesh filename="package://rvizglabre/modelos/sia10f/collision/motoman_axis_e.stl"/>
      </geometry>
      <material name="yellow"/>
    </collision>
  </link>
  <link name="link_4">
    <visual>
      <origin rpy="1.57 -3.1415 0" xyz="0 0 0"/>
      <geometry>
        <mesh filename="package://rvizglabre/modelos/sia10f/visual/motoman_axis_u.stl"/>
      </geometry>
      <material name="blue"/>
    </visual>
    <collision>
      <origin rpy="1.57 -3.1415 0" xyz="0 0 0"/>
      <geometry>
        <mesh filename="package://rvizglabre/modelos/sia10f/collision/motoman_axis_u.stl"/>
      </geometry>
      <material name="yellow"/>
    </collision>
  </link>
  <link name="link_5">
    <visual>
      <origin rpy="0 0 3.1416" xyz="0 0 0"/>
      <geometry>
        <mesh filename="package://rvizglabre/modelos/sia10f/visual/motoman_axis_r.stl"/>
      </geometry>
      <material name="silver"/>
    </visual>
    <collision>
      <origin rpy="0 0 3.1416" xyz="0 0 0"/>
      <geometry>
        <mesh filename="package://rvizglabre/modelos/sia10f/collision/motoman_axis_r.stl"/>
      </geometry>
      <material name="yellow"/>
    </collision>
  </link>
  <link name="link_6">
    <visual>
      <origin rpy="-1.57 0 3.1416" xyz="0 0 0"/>
      <geometry>
        <mesh filename="package://rvizglabre/modelos/sia10f/visual/motoman_axis_b.stl"/>
      </geometry>
      <material name="blue"/>
    </visual>
    <collision>
      <origin rpy="-1.57 0 3.1416" xyz="0 0 0"/>
      <geometry>
        <mesh filename="package://rvizglabre/modelos/sia10f/collision/motoman_axis_b.stl"/>
      </geometry>
      <material name="yellow"/>
    </collision>
  </link>
  <link name="link_7">
    <visual>
      <geometry>
        <mesh filename="package://rvizglabre/modelos/sia10f/visual/motoman_axis_t.stl"/>
      </geometry>
      <material name="silver"/>
    </visual>
    <collision>
      <geometry>
        <mesh filename="package://rvizglabre/modelos/sia10f/collision/motoman_axis_t.stl"/>
      </geometry>
      <material name="yellow"/>
    </collision>
  </link>
  <joint name="joint_1" type="revolute">
    <parent link="base_link"/>
    <child link="link_1"/>
    <origin rpy="0 0 0" xyz="0 0 0.36"/>
    <axis xyz="0 0 1"/>
    <limit effort="100" lower="-3.1415" upper="3.1415" velocity="2.9670" />
  </joint>
  <joint name="joint_2" type="revolute">
    <parent link="link_1"/>
    <child link="link_2"/>
    <origin rpy="0 0 0" xyz="0 0 0"/>
    <axis xyz="0 1 0"/>
    <limit effort="100" lower="-1.9198" upper="1.9198" velocity="2.9670" />
  </joint>
  <joint name="joint_3" type="revolute">
    <parent link="link_2"/>
    <child link="link_3"/>
    <origin rpy="0 0 0" xyz="0 0 0.36"/>
    <axis xyz="0 0 1"/>
    <limit effort="100" lower="-2.9670" upper="2.9670" velocity="2.9670" />
  </joint>
  <joint name="joint_4" type="revolute">
    <parent link="link_3"/>
    <child link="link_4"/>
    <origin rpy="0 0 0" xyz="0 0 0"/>
    <axis xyz="0 -1 0"/>
    <limit effort="100" lower="-2.3561" upper="2.3561" velocity="2.9670" />
  </joint>
  <joint name="joint_5" type="revolute">
    <parent link="link_4"/>
    <child link="link_5"/>
    <origin rpy="0 0 0" xyz="0 0 0.360"/>
    <axis xyz="0 0 -1"/>
    <limit effort="100" lower="-3.1415" upper="3.1415" velocity="3.4906" />
  </joint>
  <joint name="joint_6" type="revolute">
    <parent link="link_5"/>
    <child link="link_6"/>
    <origin rpy="0 0 0" xyz="0 0 0"/>
    <axis xyz="0 -1 0"/>
    <limit effort="100" lower="-1.9198" upper="1.9198" velocity="3.4906" />
  </joint>
  <joint name="joint_7" type="revolute">
    <parent link="link_6"/>
    <child link="link_7"/>
    <origin rpy="0 0 0" xyz="0 0 0.155"/>
    <axis xyz="0 0 -1"/>
    <limit effort="100" lower="-3.1415" upper="3.1415" velocity="6.9813" />
  </joint>
  <link name="base"/>
  <joint name="link_2-base" type="fixed">
    <origin rpy="0 0 0" xyz="0 0 0"/>
    <parent link="link_2"/>
    <child link="base"/>
  </joint>
</robot>
