<?xml version="1.0" ?>
<robot name="kuka_AllegroHandR">
  
	<WeightSE3 rho_t="0.05" rho_r="0.05" />
  <link name="base">
    <inertial>
      <mass value="2.7"/>
      <origin rpy="0 0 0" xyz="0 0 0.055"/>
      <inertia ixx="0.00603" ixy="0" ixz="0" iyy="0.00603" iyz="0" izz="0.006615"/>
    </inertial>
    <collision>
      <origin rpy="0 0 0" xyz="0 0 0.055"/>
      <geometry>
        <cylinder length="0.11" radius="0.08"/>
      </geometry>
      <material>
	<color rgba="1 0.5 0 1"/>
      </material>
    </collision>
    <visual>
      <origin rpy="0 0 0" xyz="0 0 0"/>
      <geometry>
        <mesh filename="file:///home/users/aleix.ripoll/robotFIK_ws/src/robotfik/urdf/kuka_lwr/base.dae" scale="0.001 0.001 0.001"/>
      </geometry>
    </visual>
  </link>
  <link name="link1">
    <inertial>
      <mass value="2.7082"/>
      <origin rpy="0 0 0" xyz="0 0.01698 -0.05913"/>
      <inertia ixx="0.0123449" ixy="0" ixz="0" iyy="0.0123449" iyz="0" izz="3.9396351"/>
    </inertial>
    <collision>
      <origin rpy="0 0 0" xyz="0 0 -0.1"/>
      <geometry>
        <cylinder length="0.2" radius="0.08"/>
      </geometry>
      <material>
	<color rgba="1 0.5 0 1"/>
      </material>
    </collision>
    <collision>
      <origin rpy="0 0 0" xyz="0 0 0"/>
      <geometry>
        <sphere radius="0.1"/>
      </geometry>
      <material>
	<color rgba="1 0.5 0 1"/>
      </material>
    </collision>
    <visual>
      <origin rpy="0 0 0" xyz="0 0 0"/>
      <geometry>
        <mesh filename="file:///home/users/aleix.ripoll/robotFIK_ws/src/robotfik/urdf/kuka_lwr/link1.dae" scale="0.001 0.001 0.001"/>
      </geometry>
    </visual>
  </link>
  <link name="link2">
    <inertial>
      <mass value="2.71"/>
      <origin rpy="0 0 0" xyz="0 0.1109 0.0141"/>
      <inertia ixx="0.0123531" ixy="0" ixz="0" iyy="0.0123531" iyz="0" izz="3.9396395"/>
    </inertial>
    <collision>
      <origin rpy="-1.57079632679 0 0" xyz="0 0.1 0"/>
      <geometry>
        <cylinder length="0.2" radius="0.08"/>
      </geometry>
      <material>
	<color rgba="1 0.5 0 1"/>
      </material>
    </collision>
    <visual>
      <origin rpy="0 0 0" xyz="0 0 0"/>
      <geometry>
        <mesh filename="file:///home/users/aleix.ripoll/robotFIK_ws/src/robotfik/urdf/kuka_lwr/link2.dae" scale="0.001 0.001 0.001"/>
      </geometry>
    </visual>
  </link>
  <link name="link3">
    <inertial>
      <mass value="2.5374"/>
      <origin rpy="0 0 0" xyz="0 -0.01628 0.06621"/>
      <inertia ixx="0.0115663" ixy="0" ixz="0" iyy="0.0115663" iyz="0" izz="1.5369966"/>
    </inertial>
    <collision>
      <origin rpy="0 0 0" xyz="0 0 0.1"/>
      <geometry>
        <cylinder length="0.2" radius="0.08"/>
      </geometry>
      <material>
	<color rgba="1 0.5 0 1"/>
      </material>
    </collision>
    <collision>
      <origin rpy="0 0 0" xyz="0 0 0.2"/>
      <geometry>
        <sphere radius="0.1"/>
      </geometry>
      <material>
	<color rgba="1 0.5 0 1"/>
      </material>
    </collision>
    <visual>
      <origin rpy="0 0 0" xyz="0 0 0.2"/>
      <geometry>
        <mesh filename="file:///home/users/aleix.ripoll/robotFIK_ws/src/robotfik/urdf/kuka_lwr/link3.dae" scale="0.001 0.001 0.001"/>
      </geometry>
    </visual>
  </link>
  <link name="link4">
    <inertial>
      <mass value="2.5053"/>
      <origin rpy="0 0 0" xyz="0 -0.10538 0.01525"/>
      <inertia ixx="0.01142" ixy="0" ixz="0" iyy="0.01142" iyz="0" izz="1.536918"/>
    </inertial>
    <collision>
      <origin rpy="-1.57079632679 0 0" xyz="0 -0.1 0"/>
      <geometry>
        <cylinder length="0.2" radius="0.08"/>
      </geometry>
      <material>
	<color rgba="1 0.5 0 1"/>
      </material>
    </collision>
    <visual>
      <origin rpy="3.141592654 3.141592654 0" xyz="0 0 0"/>
      <geometry>
        <mesh filename="file:///home/users/aleix.ripoll/robotFIK_ws/src/robotfik/urdf/kuka_lwr/link4.dae" scale="0.001 0.001 0.001"/>
      </geometry>
    </visual>
  </link>
  <link name="link5">
    <inertial>
      <mass value="1.3028"/>
      <origin rpy="0 0 0" xyz="0 0.01566 0.12511"/>
      <inertia ixx="0.0055152" ixy="0" ixz="0" iyy="0.0055152" iyz="0" izz="0.6011519"/>
    </inertial>
    <collision>
      <origin rpy="0 0 0" xyz="0 0 0.065"/>
      <geometry>
        <cylinder length="0.13" radius="0.08"/>
      </geometry>
      <material>
	<color rgba="1 0.5 0 1"/>
      </material>
    </collision>
    <visual>
      <origin rpy="0 0 0" xyz="0 0 0.19"/>
      <geometry>
        <mesh filename="file:///home/users/aleix.ripoll/robotFIK_ws/src/robotfik/urdf/kuka_lwr/link5.dae" scale="0.001 0.001 0.001"/>
      </geometry>
    </visual>
  </link>
  <link name="link6">
    <inertial>
      <mass value="1.5686"/>
      <origin rpy="0 0 0" xyz="0 0.00283 -0.00228"/>
      <inertia ixx="0.0040156" ixy="0" ixz="0" iyy="0.0040156" iyz="0" izz="0.5783556"/>
    </inertial>
    <collision>
      <origin rpy="0 0 0" xyz="0 -0.005 -0.0075"/>
      <geometry>
        <sphere radius="0.085"/>
      </geometry>
      <material>
	<color rgba="1 0.5 0 1"/>
      </material>
    </collision>
    <visual>
      <origin rpy="0 0 0" xyz="0 0 0"/>
      <geometry>
        <mesh filename="file:///home/users/aleix.ripoll/robotFIK_ws/src/robotfik/urdf/kuka_lwr/link6.dae" scale="0.001 0.001 0.001"/>
      </geometry>
    </visual>
  </link>
  <link name="link7">
    <inertial>
      <mass value="0.1943"/>
      <origin rpy="0 0 0" xyz="0 0 0.06031"/>
      <inertia ixx="0.0000923" ixy="0" ixz="0" iyy="0.0000923" iyz="0" izz="0.5744954"/>
    </inertial>
    <collision>
      <origin rpy="0 0 0" xyz="0 0 0.0685"/>
      <geometry>
        <cylinder length="0.023" radius="0.0505"/>
      </geometry>
      <material>
	<color rgba="0 0 0 1"/>
      </material>
    </collision>
    <visual>
      <origin rpy="0 0 0" xyz="0 0 0.078"/>
      <geometry>
        <mesh filename="file:///home/users/aleix.ripoll/robotFIK_ws/src/robotfik/urdf/kuka_lwr/link7.dae" scale="0.001 0.001 0.001"/>
      </geometry>
    </visual>
  </link>
  <joint type="revolute" name="joint1">
    <parent link="base"/>
    <child link="link1"/>
    <origin rpy="0 0 0" xyz="0 0 0.31"/>
    <axis xyz="0 0 1"/>
    <limit velocity="1.6" effort="150" lower="-2.96705972839" upper="2.96705972839"/>
  </joint>
  <joint type="revolute" name="joint2">
    <parent link="link1"/>
    <child link="link2"/>
    <origin rpy="1.57079632679 0 0" xyz="0 0 0"/>
    <axis xyz="0 0 1"/>
    <limit velocity="1.6" effort="150" lower="-2.09439510239" upper="2.09439510239"/>
  </joint>
  <joint type="revolute" name="joint3">
    <parent link="link2"/>
    <child link="link3"/>
    <origin rpy="-1.57079632679 0 0" xyz="0 0.2 0"/>
    <axis xyz="0 0 1"/>
    <limit velocity="1.6" effort="150" lower="-2.96705972839" upper="2.96705972839"/>
  </joint>
  <joint type="revolute" name="joint4">
    <parent link="link3"/>
    <child link="link4"/>
    <origin rpy="-1.57079632679 0 0" xyz="0 0 0.2"/>
    <axis xyz="0 0 1"/>
    <limit velocity="1.6" effort="150" lower="-2.09439510239" upper="2.09439510239"/>
  </joint>
  <joint type="revolute" name="joint5">
    <parent link="link4"/>
    <child link="link5"/>
    <origin rpy="1.57079632679 0 0" xyz="0 -0.2 0"/>
    <axis xyz="0 0 1"/>
    <limit velocity="1.6" effort="150" lower="-2.96705972839" upper="2.96705972839"/>
  </joint>
  <joint type="revolute" name="joint6">
    <parent link="link5"/>
    <child link="link6"/>
    <origin rpy="1.57079632679 0 0" xyz="0 0 0.19"/>
    <axis xyz="0 0 1"/>
    <limit velocity="1.6" effort="150" lower="-2.26892802759" upper="2.26892802759"/>
  </joint>
  <joint type="revolute" name="joint7">
    <parent link="link6"/>
    <child link="link7"/>
    <origin rpy="-1.57079632679 0 0" xyz="0 0 0"/>
    <axis xyz="0 0 1"/>
    <limit velocity="1.6" effort="150" lower="-2.96705972839" upper="2.96705972839"/>
  </joint>
  

   <joint name="SupportJoint" type="fixed">
    <parent link="link7"/>
    <child link="Support"/>
    <origin rpy="0 0 1.570796327" xyz="0 0 0.1089"/>
  </joint>
  <link name="Support">
    <visual>
      <geometry>
        <mesh filename="file:///home/users/aleix.ripoll/robotFIK_ws/src/robotfik/urdf/UR5_DAE/visual/AH_support.dae" scale="0.001 0.001 0.001"/>
      </geometry>
    </visual>
    <collision>
      <material name="grey"/>
      <origin xyz="0 0 -0.0055" rpy="0 0 1.570796327"/>
      <geometry>
         <cylinder radius="0.0355" length="0.043"/>
      </geometry>
    </collision>
  </link>
  <joint name="PalmJoint" type="fixed">
    <parent link="Support"/>
    <child link="Palm"/>
    <origin rpy="0 0 1.570796327" xyz="0 0.009 0.111"/>
  </joint>
  <link name="Palm">
    <visual>
      <geometry>
	<mesh filename="file:///home/users/aleix.ripoll/robotFIK_ws/src/robotfik/urdf/AllegroHand/right/base_link_right.dae" scale="0.001 0.001 0.001"/>
      </geometry>
    </visual>
    <collision>
      <material name="black"/>
	<origin xyz="-0.009300 0 -0.0475" />
	<geometry>
	  <box size="0.0408 0.1130 0.095" />
	</geometry>
    </collision>
  </link>
  <link name="Index-base">
    <visual>
      <geometry>
        <mesh filename="file:///home/users/aleix.ripoll/robotFIK_ws/src/robotfik/urdf/AllegroHand/right/link_0_0.dae" scale="0.001 0.001 0.001"/>
      </geometry>
      <origin xyz="0 0 0.0164" />
    </visual>
    <collision>
      <material name="black"/>
      <geometry>
        <box size="0.0196 0.0275 0.0164" />
      </geometry>
      <origin xyz="0 0 0.0082" />
    </collision>
  </link>
  <joint name="joint_0.0" type="revolute">
      <axis xyz="0 0 1" />
      <limit effort="1" lower="-0.47" upper="0.47" velocity="1" />
      <parent link="Palm" />
      <child link="Index-base" />
      <origin rpy="-0.08726646255 0 0" xyz="0 0.0435 -0.001542" />
  </joint>
  <link name="Index-proximal">
    <visual>
      <geometry>
        <mesh filename="file:///home/users/aleix.ripoll/robotFIK_ws/src/robotfik/urdf/AllegroHand/right/link_1_0.dae" scale="0.001 0.001 0.001"/>
      </geometry>
      <origin rpy="1.5707963 -1.5707963 0" />
    </visual>
    <collision>
      <material name="black"/>
      <geometry>
        <box size="0.0196 0.0275 0.054" />
      </geometry>
      <origin xyz="0 0 0.027" />
    </collision>
  </link>
  <joint name="joint_1.0" type="revolute">
      <limit effort="1" lower="-0.196" upper="1.61" velocity="1" />
      <axis xyz="0 1 0" />
      <parent link="Index-base" />
      <child link="Index-proximal" />
      <origin xyz="0 0 0.0164" />
  </joint>
  <link name="Index-distal">
    <visual>
      <geometry>
        <mesh filename="file:///home/users/aleix.ripoll/robotFIK_ws/src/robotfik/urdf/AllegroHand/right/link_2_0.dae" scale="0.001 0.001 0.001"/>
      </geometry>
      <origin rpy="-1.5707963 -1.5707963 0" />
    </visual>
    <collision>
      <material name="black"/>
      <geometry>
        <box size="0.0196 0.0275 0.0384" />
      </geometry>
      <origin xyz="0 0 0.0192" />
    </collision>
  </link>
  <joint name="joint_2.0" type="revolute">
      <axis xyz="0 1 0" />
      <limit effort="1" lower="-0.174" upper="1.709" velocity="1" />
      <parent link="Index-proximal" />
      <child link="Index-distal" />
      <origin xyz="0 0 0.054" />
  </joint>
  <link name="Index-last">
    <visual>
      <geometry>
        <mesh filename="file:///home/users/aleix.ripoll/robotFIK_ws/src/robotfik/urdf/AllegroHand/right/link_3_0.dae" scale="0.001 0.001 0.001"/>
      </geometry>
      <origin rpy="-1.5707963 -1.5707963 0" />
    </visual>
    <collision>
      <material name="black"/>
      <geometry>
        <box size="0.0196 0.0275 0.0267" />
      </geometry>
      <origin xyz="0 0 0.01335" />
    </collision>
  </link>
  <joint name="joint_3.0" type="revolute">
      <axis xyz="0 1 0" />
      <limit effort="1" lower="-0.227" upper="1.618" velocity="1" />
      <parent link="Index-distal" />
      <child link="Index-last" />
      <origin xyz="0 0 0.0384" />
  </joint>
  <link name="link_3_0_tip">
    <visual>
      <geometry>
        <mesh filename="file:///home/users/aleix.ripoll/robotFIK_ws/src/robotfik/urdf/AllegroHand/right/sensing_tip.dae" scale="0.001 0.001 0.001"/>
      </geometry>
      <origin rpy="1.5707963 0 1.5707963" xyz="0.0038 0 0.0142" />
    </visual>
    <collision>
      <material name="white">
        <color rgba="1 1 1 1"/>
      </material>
      <geometry>
        <box size="0.019 0.023 0.025" />
      </geometry>
      <origin xyz="0.0043 0 0.0079" />
    </collision>
    <collision>
      <material name="white"/>
      <geometry>
        <cylinder length="0.019" radius="0.0115"/>
      </geometry>
      <origin rpy="0 -1.5707963 0" xyz="0.0043 0 0.0204" />
    </collision>
  </link>
  <joint name="joint_3_0_tip" type="fixed">
      <parent link="Index-last" />
      <child link="link_3_0_tip" />
      <origin xyz="0 0 0.0267" />
  </joint>
  <link name="Medium-base">
    <visual>
      <geometry>
        <mesh filename="file:///home/users/aleix.ripoll/robotFIK_ws/src/robotfik/urdf/AllegroHand/right/link_0_0.dae" scale="0.001 0.001 0.001"/>
      </geometry>
      <origin xyz="0 0 0.0164" />
    </visual>
    <collision>
      <material name="black"/>
      <geometry>
        <box size="0.0196 0.0275 0.0164" />
      </geometry>
      <origin xyz="0 0 0.0082" />
    </collision>
  </link>
  <joint name="joint_4.0" type="revolute">
      <axis xyz="0 0 1" />
      <limit effort="1" lower="-0.47" upper="0.47" velocity="1" />
      <parent link="Palm" />
      <child link="Medium-base" />
      <origin xyz="0 0 0.0007" />
  </joint>
  <link name="Medium-proximal">
    <visual>
      <geometry>
        <mesh filename="file:///home/users/aleix.ripoll/robotFIK_ws/src/robotfik/urdf/AllegroHand/right/link_1_0.dae" scale="0.001 0.001 0.001"/>
      </geometry>
      <origin rpy="1.5707963 -1.5707963 0" />
    </visual>
    <collision>
      <material name="black"/>
      <geometry>
        <box size="0.0196 0.0275 0.054" />
      </geometry>
      <origin xyz="0 0 0.027" />
    </collision>
  </link>
  <joint name="joint_5.0" type="revolute">
      <limit effort="1" lower="-0.196" upper="1.61" velocity="1" />
      <axis xyz="0 1 0" />
      <parent link="Medium-base" />
      <child link="Medium-proximal" />
      <origin xyz="0 0 0.0164" />
  </joint>
  <link name="Medium-distal">
    <visual>
      <geometry>
        <mesh filename="file:///home/users/aleix.ripoll/robotFIK_ws/src/robotfik/urdf/AllegroHand/right/link_2_0.dae" scale="0.001 0.001 0.001"/>
      </geometry>
      <origin rpy="-1.5707963 -1.5707963 0" />
    </visual>
    <collision>
      <material name="black"/>
      <geometry>
        <box size="0.0196 0.0275 0.0384" />
      </geometry>
      <origin xyz="0 0 0.0192" />
    </collision>
  </link>
  <joint name="joint_6.0" type="revolute">
      <axis xyz="0 1 0" />
      <limit effort="1" lower="-0.174" upper="1.709" velocity="1" />
      <parent link="Medium-proximal" />
      <child link="Medium-distal" />
      <origin xyz="0 0 0.054" />
  </joint>
  <link name="Medium-last">
    <visual>
      <geometry>
        <mesh filename="file:///home/users/aleix.ripoll/robotFIK_ws/src/robotfik/urdf/AllegroHand/right/link_3_0.dae" scale="0.001 0.001 0.001"/>
      </geometry>
      <origin rpy="-1.5707963 -1.5707963 0" />
    </visual>
    <collision>
      <material name="black"/>
      <geometry>
        <box size="0.0196 0.0275 0.0267" />
      </geometry>
      <origin xyz="0 0 0.01335" />
    </collision>
  </link>
  <joint name="joint_7.0" type="revolute">
      <axis xyz="0 1 0" />
      <limit effort="1" lower="-0.227" upper="1.618" velocity="1" />
      <parent link="Medium-distal" />
      <child link="Medium-last" />
      <origin xyz="0 0 0.0384" />
  </joint>
  <link name="link_7_0_tip">
    <visual>
      <geometry>
        <mesh filename="file:///home/users/aleix.ripoll/robotFIK_ws/src/robotfik/urdf/AllegroHand/right/sensing_tip.dae" scale="0.001 0.001 0.001"/>
      </geometry>
      <origin rpy="1.5707963 0 1.5707963" xyz="0.0038 0 0.0142" />
    </visual>
    <collision>
      <material name="white"/>
      <geometry>
        <box size="0.019 0.023 0.025" />
      </geometry>
      <origin xyz="0.0043 0 0.0079" />
    </collision>
    <collision>
      <material name="white"/>
      <geometry>
        <cylinder length="0.019" radius="0.0115"/>
      </geometry>
      <origin rpy="0 -1.5707963 0" xyz="0.0043 0 0.0204" />
    </collision>
  </link>
  <joint name="joint_7_0_tip" type="fixed">
      <parent link="Medium-last" />
      <child link="link_7_0_tip" />
      <origin xyz="0 0 0.0267" />
  </joint>
  <link name="Ring-base">
    <visual>
      <geometry>
        <mesh filename="file:///home/users/aleix.ripoll/robotFIK_ws/src/robotfik/urdf/AllegroHand/right/link_0_0.dae" scale="0.001 0.001 0.001"/>
      </geometry>
      <origin xyz="0 0 0.0164" />
    </visual>
    <collision>
      <material name="black"/>
      <geometry>
        <box size="0.0196 0.0275 0.0164" />
      </geometry>
      <origin xyz="0 0 0.0082" />
    </collision>
  </link>
  <joint name="joint_8.0" type="revolute">
      <axis xyz="0 0 1" />
      <limit effort="1" lower="-0.47" upper="0.47" velocity="1" />
      <parent link="Palm" />
      <child link="Ring-base" />
      <origin rpy="0.08726646255 0 0" xyz="0 -0.0435 -0.001542" />
  </joint>
  <link name="Ring-proximal">
    <visual>
      <geometry>
        <mesh filename="file:///home/users/aleix.ripoll/robotFIK_ws/src/robotfik/urdf/AllegroHand/right/link_1_0.dae" scale="0.001 0.001 0.001"/>
      </geometry>
      <origin rpy="1.5707963 -1.5707963 0" />
    </visual>
    <collision>
      <material name="black"/>
      <geometry>
        <box size="0.0196 0.0275 0.054" />
      </geometry>
      <origin xyz="0 0 0.027" />
    </collision>
  </link>
  <joint name="joint_9.0" type="revolute">
      <limit effort="1" lower="-0.196" upper="1.61" velocity="1" />
      <axis xyz="0 1 0" />
      <parent link="Ring-base" />
      <child link="Ring-proximal" />
      <origin xyz="0 0 0.0164" />
  </joint>
  <link name="Ring-distal">
    <visual>
      <geometry>
        <mesh filename="file:///home/users/aleix.ripoll/robotFIK_ws/src/robotfik/urdf/AllegroHand/right/link_2_0.dae" scale="0.001 0.001 0.001"/>
      </geometry>
      <origin rpy="-1.5707963 -1.5707963 0" />
    </visual>
    <collision>
      <material name="black"/>
      <geometry>
        <box size="0.0196 0.0275 0.0384" />
      </geometry>
      <origin xyz="0 0 0.0192" />
    </collision>
  </link>
  <joint name="joint_10.0" type="revolute">
      <axis xyz="0 1 0" />
      <limit effort="1" lower="-0.174" upper="1.709" velocity="1" />
      <parent link="Ring-proximal" />
      <child link="Ring-distal" />
      <origin xyz="0 0 0.054" />
  </joint>
  <link name="Ring-last">
    <visual>
      <geometry>
        <mesh filename="file:///home/users/aleix.ripoll/robotFIK_ws/src/robotfik/urdf/AllegroHand/right/link_3_0.dae" scale="0.001 0.001 0.001"/>
      </geometry>
      <origin rpy="-1.5707963 -1.5707963 0" />
    </visual>
    <collision>
      <material name="black"/>
      <geometry>
        <box size="0.0196 0.0275 0.0267" />
      </geometry>
      <origin xyz="0 0 0.01335" />
    </collision>
  </link>
  <joint name="joint_11.0" type="revolute">
      <axis xyz="0 1 0" />
      <limit effort="1" lower="-0.227" upper="1.618" velocity="1" />
      <parent link="Ring-distal" />
      <child link="Ring-last" />
      <origin xyz="0 0 0.0384" />
  </joint>
  <link name="link_11_0_tip">
    <visual>
      <geometry>
        <mesh filename="file:///home/users/aleix.ripoll/robotFIK_ws/src/robotfik/urdf/AllegroHand/right/sensing_tip.dae" scale="0.001 0.001 0.001"/>
      </geometry>
      <origin rpy="1.5707963 0 1.5707963" xyz="0.0038 0 0.0142" />
    </visual>
    <collision>
      <material name="white"/>
      <geometry>
        <box size="0.019 0.023 0.025" />
      </geometry>
      <origin xyz="0.0043 0 0.0079" />
    </collision>
    <collision>
      <material name="white"/>
      <geometry>
        <cylinder length="0.019" radius="0.0115"/>
      </geometry>
      <origin rpy="0 -1.5707963 0" xyz="0.0043 0 0.0204" />
    </collision>
  </link>
  <joint name="joint_11_0_tip" type="fixed">
      <parent link="Ring-last" />
      <child link="link_11_0_tip" />
      <origin xyz="0 0 0.0267" />
  </joint>
  <link name="Thumb-base">
    <visual>
      <geometry>
        <mesh filename="file:///home/users/aleix.ripoll/robotFIK_ws/src/robotfik/urdf/AllegroHand/right/link_12_0_right.dae" scale="0.001 0.001 0.001"/>
      </geometry>
      <origin rpy="1.570796327 0 -1.570796327" xyz="-0.02775 0 0" />
    </visual>
    <collision>
      <material name="black"/>
      <geometry>
        <box size="0.0358 0.034 0.0455" />
      </geometry>
      <origin xyz="-0.0179 0.009 0.0145" />
    </collision>
  </link>
  <joint name="joint_12.0" type="revolute">
      <axis xyz="-1 0 0" />
      <limit effort="1" lower="0.263" upper="1.396" velocity="1" />
      <parent link="Palm" />
      <child link="Thumb-base" />
      <origin rpy="0 -1.65806278845 -1.5707963259" xyz="-0.0182 0.019333 -0.045987" />
  </joint>
  <link name="Thumb-proximal">
    <visual>
      <geometry>
        <mesh filename="file:///home/users/aleix.ripoll/robotFIK_ws/src/robotfik/urdf/AllegroHand/right/link_13_0.dae" scale="0.001 0.001 0.001"/>
      </geometry>
      <origin xyz="0 0 0.016000001" />
    </visual>
    <collision>
      <material name="black"/>
      <geometry>
        <box size="0.0196 0.0275 0.0177" />
      </geometry>
      <origin xyz="0 0 0.00885" />
    </collision>
  </link>
  <joint name="joint_13.0" type="revolute">
      <axis xyz="0 0 1" />
      <limit effort="1" lower="-0.105" upper="1.163" velocity="1" />
      <parent link="Thumb-base" />
      <child link="Thumb-proximal" />
      <origin xyz="-0.027 0.005 0.0399" />
  </joint>
  <link name="Thumb-distal">
    <visual>
      <geometry>
        <mesh filename="file:///home/users/aleix.ripoll/robotFIK_ws/src/robotfik/urdf/AllegroHand/right/link_14_0.dae" scale="0.001 0.001 0.001"/>
      </geometry>
      <origin rpy="-1.5707963259 1.5707963259 0" />
    </visual>
    <collision>
      <material name="black"/>
      <geometry>
        <box size="0.0196 0.0275 0.0514" />
      </geometry>
      <origin xyz="0 0 0.0257" />
    </collision>
  </link>
  <joint name="joint_14.0" type="revolute">
      <axis xyz="0 1 0" />
      <limit effort="1" lower="-0.189" upper="1.644" velocity="1" />
      <parent link="Thumb-proximal" />
      <child link="Thumb-distal" />
      <origin xyz="0 0 0.0177" />
  </joint>
  <link name="Thumb-last">
    <visual>
      <geometry>
        <mesh filename="file:///home/users/aleix.ripoll/robotFIK_ws/src/robotfik/urdf/AllegroHand/right/link_15_0.dae" scale="0.001 0.001 0.001"/>
      </geometry>
      <origin rpy="1.5707963259 1.5707963259 0" />
    </visual>
    <collision>
      <material name="black"/>
      <geometry>
        <box size="0.0196 0.0275 0.0423" />
      </geometry>
      <origin xyz="0 0 0.02115" />
    </collision>
  </link>
  <joint name="joint_15.0" type="revolute">
      <axis xyz="0 1 0" />
      <limit effort="1" lower="-0.162" upper="1.719" velocity="1" />
      <parent link="Thumb-distal" />
      <child link="Thumb-last" />
      <origin xyz="0 0 0.0514" />
  </joint>
  <link name="link_15_0_tip">
    <visual>
      <geometry>
        <mesh filename="file:///home/users/aleix.ripoll/robotFIK_ws/src/robotfik/urdf/AllegroHand/right/sensing_tip.dae" scale="0.001 0.001 0.001"/>
      </geometry>
      <origin rpy="1.5707963 0 1.5707963" xyz="0.0038 0 0.0142" />
    </visual>
    <collision>
      <material name="white"/>
      <geometry>
        <box size="0.019 0.023 0.025" />
      </geometry>
      <origin xyz="0.0043 0 0.0079" />
    </collision>
    <collision>
      <material name="white"/>
      <geometry>
        <cylinder length="0.019" radius="0.0115"/>
      </geometry>
      <origin rpy="0 -1.5707963 0" xyz="0.0043 0 0.0204" />
    </collision>
  </link>
  <joint name="joint_15_0_tip" type="fixed">
      <parent link="Thumb-last" />
      <child link="link_15_0_tip" />
      <origin xyz="0 0 0.0423" />
  </joint>
</robot>

