<?xml version="1.0" ?>
<robot name="UR5AHR_T_UR5AHL">
  
  <link name="base_link">
    <origin xyz="0 0 0" rpy="0 0 0"/>
    <visual>
      	      <origin xyz="0 0 0" rpy="1.570796327 0 0"/>
      <geometry>
        <mesh filename="file:///home/users/aleix.ripoll/robotFIK_ws/src/robotfik/urdf/structureT_DAE/structure.dae"/>
      </geometry>
    </visual>
    <collision>
      <origin xyz="0 0 -0.63" rpy="0 0 0"/>
      <geometry>
        <cylinder radius="0.045" length="1.26"/>
      </geometry>
      <material name="grey">
        <color rgba="0.8 0.83 0.94 1"/>
      </material>
    </collision>
    <collision>
      <origin xyz="0 0.0006 0" rpy="1.57079632679 1.570796327 1.570796327" />
      <geometry>
        <cylinder radius="0.045" length="0.3994"/>
      </geometry>
      <material name="grey"/>
    </collision>
    <collision>
      <origin xyz="-0.2447 0 0" rpy="0 -3.92699081699 -3.14159265359" />
      <geometry>
        <cylinder radius="0.0744" length="0.0632"/>
      </geometry>
      <material name="grey"/>
    </collision>
    <collision>
      <origin xyz="0.2447 0 0" rpy="0 3.92699081699 -3.14159265359" />
      <geometry>
        <cylinder radius="0.0744" length="0.0632"/>
      </geometry>
      <material name="grey"/>
    </collision>
    <collision>
      <origin xyz="0 -0.37 -0.93720454"/>
      <geometry>
        <box size="0.8 0.83 0.64559096 "/>
      </geometry>
      <material name="grey"/>
    </collision>
  </link>
  <joint name="ShoulderJoint_R" type="fixed">
    <parent link="base_link"/>
    <child link="handbase_R"/>
    <origin rpy="0 -3.92699081699 -3.14159265359" xyz="-0.23963021891 0 -0.0110" />
  </joint>
  <link name="handbase_R">
    <origin xyz="-0.23963021891 0 -0.0110" rpy="0 -3.92699081699 -3.14159265359"/>
    <visual>
      <geometry>
        <mesh filename="file:///home/users/aleix.ripoll/robotFIK_ws/src/robotfik/urdf/UR5_DAE/visual/Base.dae"/>
      </geometry>
    </visual>
    <collision>
      <material name="grey">
        <color rgba="0.44 0.44 0.44 1"/>
      </material>
      <origin xyz="0 0 0.0055"/>
      <geometry>
         <cylinder radius="0.0745" length="0.017"/>
      </geometry>
    </collision>
    <inertial>
      <mass value="4"/>
      <inertia ixx="0.00443333156" ixy="0" ixz="0" iyy="0.00443333156" iyz="0" izz="0.0072"/>
    </inertial>
  </link>
  <joint name="ShoulderPanJoint_R" type="revolute">
    <parent link="handbase_R"/>
    <child link="Shoulder_R"/>
    <origin xyz="0 0 0.080833" rpy="0 0 0"/>
    <axis xyz="0 0 1"/>
    <limit effort="150" lower="-6.2831853" upper="6.2831853" velocity="3.15"/>
  </joint>
  <link name="Shoulder_R">
    <visual>
      <geometry>
        <mesh filename="file:///home/users/aleix.ripoll/robotFIK_ws/src/robotfik/urdf/UR5_DAE/visual/Shoulder.dae"/>
      </geometry>
    </visual>
    <collision>
      <material name="black">
        <color rgba="0.09 0.09 0.09 1"/>
      </material>
      <origin xyz="0 0 -0.003"/>
      <geometry>
         <cylinder radius="0.0638" length="0.143"/>
      </geometry>
    </collision>
    <inertial>
      <mass value="3.7"/>
      <inertia ixx="0.010267495893" ixy="0" ixz="0" iyy="0.010267495893" iyz="0" izz="0.00666"/>
    </inertial>
  </link>
  <joint name="ShoulderLiftJoint_R" type="revolute">
    <parent link="Shoulder_R"/>
    <child link="UpperArm_R"/>
    <origin rpy="0 1.570796325 0" xyz="0 0.13585 0"/>
    <axis xyz="0 1 0"/>
    <limit effort="150" lower="-6.2831853" upper="6.2831853" velocity="3.15"/>
  </joint>
  <link name="UpperArm_R">
    <visual>
      <geometry>
        <mesh filename="file:///home/users/aleix.ripoll/robotFIK_ws/src/robotfik/urdf/UR5_DAE/visual/UpperArm.dae"/>
      </geometry>
    </visual>
    <collision>
      <material name="black"/>
      <origin xyz="0 -0.0336 0" rpy="1.570796327 0 0"/>
      <geometry>
         <cylinder radius="0.0638" length="0.2042"/>
      </geometry>
    </collision>
    <collision>
      <material name="grey"/>
      <origin xyz="0 0 0.2125"/>
      <geometry>
         <cylinder radius="0.0588" length="0.425"/>
      </geometry>
    </collision>
    <collision>
      <material name="black"/>
      <origin xyz="0 -0.0305 0.425" rpy="1.570796327 0 0"/>
      <geometry>
         <cylinder radius="0.0638" length="0.198"/>
      </geometry>
    </collision>
    <inertial>
      <mass value="8.393"/>
      <origin xyz="0 0 0.28"/>
      <inertia ixx="0.22689067591" ixy="0" ixz="0" iyy="0.22689067591" iyz="0" izz="0.0151074"/>
    </inertial>
  </link>
  <joint name="ElbowJoint_R" type="revolute">
    <parent link="UpperArm_R"/>
    <child link="ForeArm_R"/>
    <origin xyz="0 -0.1197 0.425"/>
    <axis xyz="0 1 0"/>
    <limit effort="150" lower="-6.2831853" upper="6.2831853" velocity="3.15"/>
  </joint>
  <link name="ForeArm_R">
    <visual>
      <geometry>
        <mesh filename="file:///home/users/aleix.ripoll/robotFIK_ws/src/robotfik/urdf/UR5_DAE/visual/Forearm.dae"/>
      </geometry>
    </visual>
    <collision>
      <material name="grey"/>
      <origin xyz="0 0 0.180"/>
      <geometry>
         <cylinder radius="0.0421" length="0.424"/>
      </geometry>
    </collision>
    <collision>
      <material name="black"/>
      <origin xyz="0 0.019 0.392" rpy="1.570796327 0 0"/>
      <geometry>
         <cylinder radius="0.0421" length="0.1524"/>
      </geometry>
    </collision>
    <inertial>
      <mass value="2.275"/>
      <origin xyz="0 0 0.25"/>
      <inertia ixx="0.049443313556" ixy="0" ixz="0" iyy="0.049443313556" iyz="0" izz="0.004095"/>
    </inertial>
  </link>
  <joint name="Wrist1Joint_R" type="revolute">
    <parent link="ForeArm_R"/>
    <child link="Wrist1_R"/>
    <origin rpy="0 1.570796325 0" xyz="0 0 0.39225"/>
    <axis xyz="0 1 0"/>
    <limit effort="28" lower="-6.2831853" upper="6.2831853" velocity="3.2"/>
  </joint>
  <link name="Wrist1_R">
    <visual>
      <geometry>
        <mesh filename="file:///home/users/aleix.ripoll/robotFIK_ws/src/robotfik/urdf/UR5_DAE/visual/Wrist1.dae"/>
      </geometry>
    </visual>
    <collision>
      <material name="black"/>
      <origin xyz="0 0.093 0.019"/>
      <geometry>
         <cylinder radius="0.0421" length="0.1524"/>
      </geometry>
    </collision>
    <inertial>
      <mass value="1.219"/>
      <inertia ixx="0.111172755531" ixy="0" ixz="0" iyy="0.111172755531" iyz="0" izz="0.21942"/>
    </inertial>
  </link>
  <joint name="Wrist2Joint_R" type="revolute">
    <parent link="Wrist1_R"/>
    <child link="Wrist2_R"/>
    <origin xyz="0 0.093 0"/>
    <axis xyz="0 0 1"/>
    <limit effort="28" lower="-6.2831853" upper="6.2831853" velocity="3.2"/>
  </joint>
  <link name="Wrist2_R">
    <visual>
      <geometry>
        <mesh filename="file:///home/users/aleix.ripoll/robotFIK_ws/src/robotfik/urdf/UR5_DAE/visual/Wrist2.dae"/>
      </geometry>
    </visual>
    <collision>
      <material name="black"/>
      <origin xyz="0 0.00885 0.09475" rpy="1.570796325 0 0"/>
      <geometry>
         <cylinder radius="0.0421" length="0.1321"/>
      </geometry>
    </collision>
    <inertial>
      <mass value="1.219"/>
      <inertia ixx="0.111172755531" ixy="0" ixz="0" iyy="0.111172755531" iyz="0" izz="0.21942"/>
    </inertial>
  </link>
  <joint name="Wrist3Joint_R" type="revolute">
    <parent link="Wrist2_R"/>
    <child link="Wrist3_R"/>
    <origin xyz="0 0 0.09465"/>
    <axis xyz="0 1 0"/>
    <limit effort="28" lower="-6.2831853" upper="6.2831853" velocity="3.2"/>
  </joint>
  <link name="Wrist3_R">
    <visual>
      <geometry>
        <mesh filename="file:///home/users/aleix.ripoll/robotFIK_ws/src/robotfik/urdf/UR5_DAE/visual/Wrist3.dae"/>
      </geometry>
    </visual>
    <collision>
      <material name="grey"/>
      <origin xyz="0 0.0784 0" rpy="1.570796325 0 0"/>
      <geometry>
         <cylinder radius="0.0319" length="0.007"/>
      </geometry>
    </collision>
    <inertial>
      <mass value="0.1879"/>
      <inertia ixx="0.0171364731454" ixy="0" ixz="0" iyy="0.0171364731454" iyz="0" izz="0.033822"/>
    </inertial>
  </link>
  <joint name="SupportJoint_R" type="fixed">
    <parent link="Wrist3_R"/>
    <child link="Support_R"/>
    <origin rpy="-1.570796325 0 0" xyz="0 0.0983 0"/>
  </joint>
  <link name="Support_R">
    <visual>
      <geometry>
        <mesh filename="file:///home/users/aleix.ripoll/robotFIK_ws/src/robotfik/urdf/UR5_DAE/visual/AH_support.dae" scale="0.001 0.001 0.001"/>
      </geometry>
    </visual>
    <collision>
      <material name="grey"/>
      <origin rpy="0 0 1.570796327"/>
      <geometry>
         <cylinder radius="0.0355" length="0.032"/>
      </geometry>
    </collision>
  </link>
  <joint name="PalmJoint_R" type="fixed">
    <parent link="Support_R"/>
    <child link="Palm_R"/>
    <origin rpy="0 0 1.570796327" xyz="0.009 0 0.111"/>
  </joint>
  <link name="Palm_R">
    <visual>
      <geometry>
	<mesh filename="file:///home/users/aleix.ripoll/robotFIK_ws/src/robotfik/urdf/AllegroHand/right/base_link_right.dae" scale="0.001 0.001 0.001"/>
      </geometry>
    </visual>
    <collision>
      <material name="black"/>
	<origin xyz="-0.009300 0 -0.0475" />
	<geometry>
	  <box size="0.0408 0.1130 0.095" />
	</geometry>
    </collision>
  </link>
  <link name="Index-base_R">
    <visual>
      <geometry>
        <mesh filename="file:///home/users/aleix.ripoll/robotFIK_ws/src/robotfik/urdf/AllegroHand/right/link_0_0.dae" scale="0.001 0.001 0.001"/>
      </geometry>
      <origin xyz="0 0 0.0164" />
    </visual>
    <collision>
      <material name="black"/>
      <geometry>
        <box size="0.0196 0.0275 0.0164" />
      </geometry>
      <origin xyz="0 0 0.0082" />
    </collision>
  </link>
  <joint name="joint_0.0" type="revolute">
      <axis xyz="0 0 1" />
      <limit effort="1" lower="-0.47" upper="0.47" velocity="1" />
      <parent link="Palm_R" />
      <child link="Index-base_R" />
      <origin rpy="-0.08726646255 0 0" xyz="0 0.0435 -0.001542" />
  </joint>
  <link name="Index-proximal_R">
    <visual>
      <geometry>
        <mesh filename="file:///home/users/aleix.ripoll/robotFIK_ws/src/robotfik/urdf/AllegroHand/right/link_1_0.dae" scale="0.001 0.001 0.001"/>
      </geometry>
      <origin rpy="1.5707963 -1.5707963 0" />
    </visual>
    <collision>
      <material name="black"/>
      <geometry>
        <box size="0.0196 0.0275 0.054" />
      </geometry>
      <origin xyz="0 0 0.027" />
    </collision>
  </link>
  <joint name="joint_1.0" type="revolute">
      <limit effort="1" lower="-0.196" upper="1.61" velocity="1" />
      <axis xyz="0 1 0" />
      <parent link="Index-base_R" />
      <child link="Index-proximal_R" />
      <origin xyz="0 0 0.0164" />
  </joint>
  <link name="Index-distal_R">
    <visual>
      <geometry>
        <mesh filename="file:///home/users/aleix.ripoll/robotFIK_ws/src/robotfik/urdf/AllegroHand/right/link_2_0.dae" scale="0.001 0.001 0.001"/>
      </geometry>
      <origin rpy="-1.5707963 -1.5707963 0" />
    </visual>
    <collision>
      <material name="black"/>
      <geometry>
        <box size="0.0196 0.0275 0.0384" />
      </geometry>
      <origin xyz="0 0 0.0192" />
    </collision>
  </link>
  <joint name="joint_2.0" type="revolute">
      <axis xyz="0 1 0" />
      <limit effort="1" lower="-0.174" upper="1.709" velocity="1" />
      <parent link="Index-proximal_R" />
      <child link="Index-distal_R" />
      <origin xyz="0 0 0.054" />
  </joint>
  <link name="Index-last_R">
    <visual>
      <geometry>
        <mesh filename="file:///home/users/aleix.ripoll/robotFIK_ws/src/robotfik/urdf/AllegroHand/right/link_3_0.dae" scale="0.001 0.001 0.001"/>
      </geometry>
      <origin rpy="-1.5707963 -1.5707963 0" />
    </visual>
    <collision>
      <material name="black"/>
      <geometry>
        <box size="0.0196 0.0275 0.0267" />
      </geometry>
      <origin xyz="0 0 0.01335" />
    </collision>
  </link>
  <joint name="joint_3.0" type="revolute">
      <axis xyz="0 1 0" />
      <limit effort="1" lower="-0.227" upper="1.618" velocity="1" />
      <parent link="Index-distal_R" />
      <child link="Index-last_R" />
      <origin xyz="0 0 0.0384" />
  </joint>
  <link name="link_3_0_tip">
    <visual>
      <geometry>
        <mesh filename="file:///home/users/aleix.ripoll/robotFIK_ws/src/robotfik/urdf/AllegroHand/right/sensing_tip.dae" scale="0.001 0.001 0.001"/>
      </geometry>
      <origin rpy="1.5707963 0 1.5707963" xyz="0.0038 0 0.0142" />
    </visual>
    <collision>
      <material name="white">
        <color rgba="1 1 1 1"/>
      </material>
      <geometry>
        <box size="0.019 0.023 0.0365" />
      </geometry>
      <origin xyz="0.0043 0 0.0125" />
    </collision>
  </link>
  <joint name="joint_3_0_tip" type="fixed">
      <parent link="Index-last_R" />
      <child link="link_3_0_tip" />
      <origin xyz="0 0 0.0267" />
  </joint>
  <link name="Medium-base_R">
    <visual>
      <geometry>
        <mesh filename="file:///home/users/aleix.ripoll/robotFIK_ws/src/robotfik/urdf/AllegroHand/right/link_0_0.dae" scale="0.001 0.001 0.001"/>
      </geometry>
      <origin xyz="0 0 0.0164" />
    </visual>
    <collision>
      <material name="black"/>
      <geometry>
        <box size="0.0196 0.0275 0.0164" />
      </geometry>
      <origin xyz="0 0 0.0082" />
    </collision>
  </link>
  <joint name="joint_4.0" type="revolute">
      <axis xyz="0 0 1" />
      <limit effort="1" lower="-0.47" upper="0.47" velocity="1" />
      <parent link="Palm_R" />
      <child link="Medium-base_R" />
      <origin xyz="0 0 0.0007" />
  </joint>
  <link name="Medium-proximal_R">
    <visual>
      <geometry>
        <mesh filename="file:///home/users/aleix.ripoll/robotFIK_ws/src/robotfik/urdf/AllegroHand/right/link_1_0.dae" scale="0.001 0.001 0.001"/>
      </geometry>
      <origin rpy="1.5707963 -1.5707963 0" />
    </visual>
    <collision>
      <material name="black"/>
      <geometry>
        <box size="0.0196 0.0275 0.054" />
      </geometry>
      <origin xyz="0 0 0.027" />
    </collision>
  </link>
  <joint name="joint_5.0" type="revolute">
      <limit effort="1" lower="-0.196" upper="1.61" velocity="1" />
      <axis xyz="0 1 0" />
      <parent link="Medium-base_R" />
      <child link="Medium-proximal_R" />
      <origin xyz="0 0 0.0164" />
  </joint>
  <link name="Medium-distal_R">
    <visual>
      <geometry>
        <mesh filename="file:///home/users/aleix.ripoll/robotFIK_ws/src/robotfik/urdf/AllegroHand/right/link_2_0.dae" scale="0.001 0.001 0.001"/>
      </geometry>
      <origin rpy="-1.5707963 -1.5707963 0" />
    </visual>
    <collision>
      <material name="black"/>
      <geometry>
        <box size="0.0196 0.0275 0.0384" />
      </geometry>
      <origin xyz="0 0 0.0192" />
    </collision>
  </link>
  <joint name="joint_6.0" type="revolute">
      <axis xyz="0 1 0" />
      <limit effort="1" lower="-0.174" upper="1.709" velocity="1" />
      <parent link="Medium-proximal_R" />
      <child link="Medium-distal_R" />
      <origin xyz="0 0 0.054" />
  </joint>
  <link name="Medium-last_R">
    <visual>
      <geometry>
        <mesh filename="file:///home/users/aleix.ripoll/robotFIK_ws/src/robotfik/urdf/AllegroHand/right/link_3_0.dae" scale="0.001 0.001 0.001"/>
      </geometry>
      <origin rpy="-1.5707963 -1.5707963 0" />
    </visual>
    <collision>
      <material name="black"/>
      <geometry>
        <box size="0.0196 0.0275 0.0267" />
      </geometry>
      <origin xyz="0 0 0.01335" />
    </collision>
  </link>
  <joint name="joint_7.0" type="revolute">
      <axis xyz="0 1 0" />
      <limit effort="1" lower="-0.227" upper="1.618" velocity="1" />
      <parent link="Medium-distal_R" />
      <child link="Medium-last_R" />
      <origin xyz="0 0 0.0384" />
  </joint>
  <link name="link_7_0_tip">
    <visual>
      <geometry>
        <mesh filename="file:///home/users/aleix.ripoll/robotFIK_ws/src/robotfik/urdf/AllegroHand/right/sensing_tip.dae" scale="0.001 0.001 0.001"/>
      </geometry>
      <origin rpy="1.5707963 0 1.5707963" xyz="0.0038 0 0.0142" />
    </visual>
    <collision>
      <material name="white"/>
      <geometry>
        <box size="0.019 0.023 0.0365" />
      </geometry>
      <origin xyz="0.0043 0 0.0125" />
    </collision>
  </link>
  <joint name="joint_7_0_tip" type="fixed">
      <parent link="Medium-last_R" />
      <child link="link_7_0_tip" />
      <origin xyz="0 0 0.0267" />
  </joint>
  <link name="Ring-base_R">
    <visual>
      <geometry>
        <mesh filename="file:///home/users/aleix.ripoll/robotFIK_ws/src/robotfik/urdf/AllegroHand/right/link_0_0.dae" scale="0.001 0.001 0.001"/>
      </geometry>
      <origin xyz="0 0 0.0164" />
    </visual>
    <collision>
      <material name="black"/>
      <geometry>
        <box size="0.0196 0.0275 0.0164" />
      </geometry>
      <origin xyz="0 0 0.0082" />
    </collision>
  </link>
  <joint name="joint_8.0" type="revolute">
      <axis xyz="0 0 1" />
      <limit effort="1" lower="-0.47" upper="0.47" velocity="1" />
      <parent link="Palm_R" />
      <child link="Ring-base_R" />
      <origin rpy="0.08726646255 0 0" xyz="0 -0.0435 -0.001542" />
  </joint>
  <link name="Ring-proximal_R">
    <visual>
      <geometry>
        <mesh filename="file:///home/users/aleix.ripoll/robotFIK_ws/src/robotfik/urdf/AllegroHand/right/link_1_0.dae" scale="0.001 0.001 0.001"/>
      </geometry>
      <origin rpy="1.5707963 -1.5707963 0" />
    </visual>
    <collision>
      <material name="black"/>
      <geometry>
        <box size="0.0196 0.0275 0.054" />
      </geometry>
      <origin xyz="0 0 0.027" />
    </collision>
  </link>
  <joint name="joint_9.0" type="revolute">
      <limit effort="1" lower="-0.196" upper="1.61" velocity="1" />
      <axis xyz="0 1 0" />
      <parent link="Ring-base_R" />
      <child link="Ring-proximal_R" />
      <origin xyz="0 0 0.0164" />
  </joint>
  <link name="Ring-distal_R">
    <visual>
      <geometry>
        <mesh filename="file:///home/users/aleix.ripoll/robotFIK_ws/src/robotfik/urdf/AllegroHand/right/link_2_0.dae" scale="0.001 0.001 0.001"/>
      </geometry>
      <origin rpy="-1.5707963 -1.5707963 0" />
    </visual>
    <collision>
      <material name="black"/>
      <geometry>
        <box size="0.0196 0.0275 0.0384" />
      </geometry>
      <origin xyz="0 0 0.0192" />
    </collision>
  </link>
  <joint name="joint_10.0" type="revolute">
      <axis xyz="0 1 0" />
      <limit effort="1" lower="-0.174" upper="1.709" velocity="1" />
      <parent link="Ring-proximal_R" />
      <child link="Ring-distal_R" />
      <origin xyz="0 0 0.054" />
  </joint>
  <link name="Ring-last_R">
    <visual>
      <geometry>
        <mesh filename="file:///home/users/aleix.ripoll/robotFIK_ws/src/robotfik/urdf/AllegroHand/right/link_3_0.dae" scale="0.001 0.001 0.001"/>
      </geometry>
      <origin rpy="-1.5707963 -1.5707963 0" />
    </visual>
    <collision>
      <material name="black"/>
      <geometry>
        <box size="0.0196 0.0275 0.0267" />
      </geometry>
      <origin xyz="0 0 0.01335" />
    </collision>
  </link>
  <joint name="joint_11.0" type="revolute">
      <axis xyz="0 1 0" />
      <limit effort="1" lower="-0.227" upper="1.618" velocity="1" />
      <parent link="Ring-distal_R" />
      <child link="Ring-last_R" />
      <origin xyz="0 0 0.0384" />
  </joint>
  <link name="link_11_0_tip">
    <visual>
      <geometry>
        <mesh filename="file:///home/users/aleix.ripoll/robotFIK_ws/src/robotfik/urdf/AllegroHand/right/sensing_tip.dae" scale="0.001 0.001 0.001"/>
      </geometry>
      <origin rpy="1.5707963 0 1.5707963" xyz="0.0038 0 0.0142" />
    </visual>
    <collision>
      <material name="white"/>
      <geometry>
        <box size="0.019 0.023 0.0365" />
      </geometry>
      <origin xyz="0.0043 0 0.0125" />
    </collision>
  </link>
  <joint name="joint_11_0_tip" type="fixed">
      <parent link="Ring-last_R" />
      <child link="link_11_0_tip" />
      <origin xyz="0 0 0.0267" />
  </joint>
  <link name="Thumb-base_R">
    <visual>
      <geometry>
        <mesh filename="file:///home/users/aleix.ripoll/robotFIK_ws/src/robotfik/urdf/AllegroHand/right/link_12_0_right.dae" scale="0.001 0.001 0.001"/>
      </geometry>
      <origin rpy="1.570796327 0 -1.570796327" xyz="-0.02775 0 0" />
    </visual>
    <collision>
      <material name="black"/>
      <geometry>
        <box size="0.0358 0.034 0.0455" />
      </geometry>
      <origin xyz="-0.0179 0.009 0.0145" />
    </collision>
  </link>
  <joint name="joint_12.0" type="revolute">
      <axis xyz="-1 0 0" />
      <limit effort="1" lower="0.263" upper="1.396" velocity="1" />
      <parent link="Palm_R" />
      <child link="Thumb-base_R" />
      <origin rpy="0 -1.65806278845 -1.5707963259" xyz="-0.0182 0.019333 -0.045987" />
  </joint>
  <link name="Thumb-proximal_R">
    <visual>
      <geometry>
        <mesh filename="file:///home/users/aleix.ripoll/robotFIK_ws/src/robotfik/urdf/AllegroHand/right/link_13_0.dae" scale="0.001 0.001 0.001"/>
      </geometry>
      <origin xyz="0 0 0.016000001" />
    </visual>
    <collision>
      <material name="black"/>
      <geometry>
        <box size="0.0196 0.0275 0.0177" />
      </geometry>
      <origin xyz="0 0 0.00885" />
    </collision>
  </link>
  <joint name="joint_13.0" type="revolute">
      <axis xyz="0 0 1" />
      <limit effort="1" lower="-0.105" upper="1.163" velocity="1" />
      <parent link="Thumb-base_R" />
      <child link="Thumb-proximal_R" />
      <origin xyz="-0.027 0.005 0.0399" />
  </joint>
  <link name="Thumb-distal_R">
    <visual>
      <geometry>
        <mesh filename="file:///home/users/aleix.ripoll/robotFIK_ws/src/robotfik/urdf/AllegroHand/right/link_14_0.dae" scale="0.001 0.001 0.001"/>
      </geometry>
      <origin rpy="-1.5707963259 1.5707963259 0" />
    </visual>
    <collision>
      <material name="black"/>
      <geometry>
        <box size="0.0196 0.0275 0.0514" />
      </geometry>
      <origin xyz="0 0 0.0257" />
    </collision>
  </link>
  <joint name="joint_14.0" type="revolute">
      <axis xyz="0 1 0" />
      <limit effort="1" lower="-0.189" upper="1.644" velocity="1" />
      <parent link="Thumb-proximal_R" />
      <child link="Thumb-distal_R" />
      <origin xyz="0 0 0.0177" />
  </joint>
  <link name="Thumb-last_R">
    <visual>
      <geometry>
        <mesh filename="file:///home/users/aleix.ripoll/robotFIK_ws/src/robotfik/urdf/AllegroHand/right/link_15_0.dae" scale="0.001 0.001 0.001"/>
      </geometry>
      <origin rpy="1.5707963259 1.5707963259 0" />
    </visual>
    <collision>
      <material name="black"/>
      <geometry>
        <box size="0.0196 0.0275 0.0423" />
      </geometry>
      <origin xyz="0 0 0.02115" />
    </collision>
  </link>
  <joint name="joint_15.0" type="revolute">
      <axis xyz="0 1 0" />
      <limit effort="1" lower="-0.162" upper="1.719" velocity="1" />
      <parent link="Thumb-distal_R" />
      <child link="Thumb-last_R" />
      <origin xyz="0 0 0.0514" />
  </joint>
  <link name="link_15_0_tip">
    <visual>
      <geometry>
        <mesh filename="file:///home/users/aleix.ripoll/robotFIK_ws/src/robotfik/urdf/AllegroHand/right/sensing_tip.dae" scale="0.001 0.001 0.001"/>
      </geometry>
      <origin rpy="1.5707963 0 1.5707963" xyz="0.0038 0 0.0142" />
    </visual>
    <collision>
      <material name="white"/>
      <geometry>
        <box size="0.019 0.023 0.0365" />
      </geometry>
      <origin xyz="0.0043 0 0.0125" />
    </collision>
  </link>
  <joint name="joint_15_0_tip" type="fixed">
      <parent link="Thumb-last_R" />
      <child link="link_15_0_tip" />
      <origin xyz="0 0 0.0423" />
  </joint>
  <joint name="ShoulderJoint_L" type="fixed">
    <parent link="base_link"/>
    <child link="handbase_L"/>
    <origin rpy="0 3.92699081699 -3.14159265359" xyz="0.23963021891 0 -0.0110" />
  </joint>
  <link name="handbase_L">
    <origin rpy="0 3.92699081699 -3.14159265359" xyz="0.23963021891 0 -0.0110"/>
    <visual>
      <geometry>
        <mesh filename="file:///home/users/aleix.ripoll/robotFIK_ws/src/robotfik/urdf/UR5_DAE/visual/Base.dae"/>
      </geometry>
    </visual>
    <collision>
      <material name="grey">
        <color rgba="0.44 0.44 0.44 1"/>
      </material>
      <origin xyz="0 0 0.0055" />
      <geometry>
         <cylinder radius="0.0745" length="0.017"/>
      </geometry>
    </collision>
    <inertial>
      <mass value="4"/>
      <inertia ixx="0.00443333156" ixy="0" ixz="0" iyy="0.00443333156" iyz="0" izz="0.0072"/>
    </inertial>
  </link>
  <joint name="ShoulderPanJoint_L" type="revolute">
    <parent link="handbase_L"/>
    <child link="Shoulder_L"/>
    <origin xyz="0 0 0.080833" rpy="0 0 0"/>
    <axis xyz="0 0 1"/>
    <limit effort="150" lower="-6.2831853" upper="6.2831853" velocity="3.15"/>
  </joint>
  <link name="Shoulder_L">
    <visual>
      <geometry>
        <mesh filename="file:///home/users/aleix.ripoll/robotFIK_ws/src/robotfik/urdf/UR5_DAE/visual/Shoulder.dae"/>
      </geometry>
    </visual>
    <collision>
      <material name="black">
        <color rgba="0.09 0.09 0.09 1"/>
      </material>
      <origin xyz="0 0 -0.003"/>
      <geometry>
         <cylinder radius="0.0638" length="0.143"/>
      </geometry>
    </collision>
    <inertial>
      <mass value="3.7"/>
      <inertia ixx="0.010267495893" ixy="0" ixz="0" iyy="0.010267495893" iyz="0" izz="0.00666"/>
    </inertial>
  </link>
  <joint name="ShoulderLiftJoint_L" type="revolute">
    <parent link="Shoulder_L"/>
    <child link="UpperArm_L"/>
    <origin rpy="0 1.570796325 0" xyz="0 0.13585 0"/>
    <axis xyz="0 1 0"/>
    <limit effort="150" lower="-6.2831853" upper="6.2831853" velocity="3.15"/>
  </joint>
  <link name="UpperArm_L">
    <visual>
      <geometry>
        <mesh filename="file:///home/users/aleix.ripoll/robotFIK_ws/src/robotfik/urdf/UR5_DAE/visual/UpperArm.dae"/>
      </geometry>
    </visual>
    <collision>
      <material name="black"/>
      <origin xyz="0 -0.0336 0" rpy="1.570796327 0 0"/>
      <geometry>
         <cylinder radius="0.0638" length="0.2042"/>
      </geometry>
    </collision>
    <collision>
      <material name="grey"/>
      <origin xyz="0 0 0.2125"/>
      <geometry>
         <cylinder radius="0.0588" length="0.425"/>
      </geometry>
    </collision>
    <collision>
      <material name="black"/>
      <origin xyz="0 -0.0305 0.425" rpy="1.570796327 0 0"/>
      <geometry>
         <cylinder radius="0.0638" length="0.198"/>
      </geometry>
    </collision>
    <inertial>
      <mass value="8.393"/>
      <origin xyz="0 0 0.28"/>
      <inertia ixx="0.22689067591" ixy="0" ixz="0" iyy="0.22689067591" iyz="0" izz="0.0151074"/>
    </inertial>
  </link>
  <joint name="ElbowJoint_L" type="revolute">
    <parent link="UpperArm_L"/>
    <child link="ForeArm_L"/>
    <origin xyz="0 -0.1197 0.425"/>
    <axis xyz="0 1 0"/>
    <limit effort="150" lower="-6.2831853" upper="6.2831853" velocity="3.15"/>
  </joint>
  <link name="ForeArm_L">
    <visual>
      <geometry>
        <mesh filename="file:///home/users/aleix.ripoll/robotFIK_ws/src/robotfik/urdf/UR5_DAE/visual/Forearm.dae"/>
      </geometry>
    </visual>
    <collision>
      <material name="grey"/>
      <origin xyz="0 0 0.180"/>
      <geometry>
         <cylinder radius="0.0421" length="0.424"/>
      </geometry>
    </collision>
    <collision>
      <material name="black"/>
      <origin xyz="0 0.019 0.392" rpy="1.570796327 0 0"/>
      <geometry>
         <cylinder radius="0.0421" length="0.1524"/>
      </geometry>
    </collision>
    <inertial>
      <mass value="2.275"/>
      <origin xyz="0 0 0.25"/>
      <inertia ixx="0.049443313556" ixy="0" ixz="0" iyy="0.049443313556" iyz="0" izz="0.004095"/>
    </inertial>
  </link>
  <joint name="Wrist1Joint_L" type="revolute">
    <parent link="ForeArm_L"/>
    <child link="Wrist1_L"/>
    <origin rpy="0 1.570796325 0" xyz="0 0 0.39225"/>
    <axis xyz="0 1 0"/>
    <limit effort="28" lower="-6.2831853" upper="6.2831853" velocity="3.2"/>
  </joint>
  <link name="Wrist1_L">
    <visual>
      <geometry>
        <mesh filename="file:///home/users/aleix.ripoll/robotFIK_ws/src/robotfik/urdf/UR5_DAE/visual/Wrist1.dae"/>
      </geometry>
    </visual>
    <collision>
      <material name="black"/>
      <origin xyz="0 0.093 0.019"/>
      <geometry>
         <cylinder radius="0.0421" length="0.1524"/>
      </geometry>
    </collision>
    <inertial>
      <mass value="1.219"/>
      <inertia ixx="0.111172755531" ixy="0" ixz="0" iyy="0.111172755531" iyz="0" izz="0.21942"/>
    </inertial>
  </link>
  <joint name="Wrist2Joint_L" type="revolute">
    <parent link="Wrist1_L"/>
    <child link="Wrist2_L"/>
    <origin xyz="0 0.093 0"/>
    <axis xyz="0 0 1"/>
    <limit effort="28" lower="-6.2831853" upper="6.2831853" velocity="3.2"/>
  </joint>
  <link name="Wrist2_L">
    <visual>
      <geometry>
        <mesh filename="file:///home/users/aleix.ripoll/robotFIK_ws/src/robotfik/urdf/UR5_DAE/visual/Wrist2.dae"/>
      </geometry>
    </visual>
    <collision>
      <material name="black"/>
      <origin xyz="0 0.00885 0.09475" rpy="1.570796325 0 0"/>
      <geometry>
         <cylinder radius="0.0421" length="0.1321"/>
      </geometry>
    </collision>
    <inertial>
      <mass value="1.219"/>
      <inertia ixx="0.111172755531" ixy="0" ixz="0" iyy="0.111172755531" iyz="0" izz="0.21942"/>
    </inertial>
  </link>
  <joint name="Wrist3Joint_L" type="revolute">
    <parent link="Wrist2_L"/>
    <child link="Wrist3_L"/>
    <origin xyz="0 0 0.09465"/>
    <axis xyz="0 1 0"/>
    <limit effort="28" lower="-6.2831853" upper="6.2831853" velocity="3.2"/>
  </joint>
  <link name="Wrist3_L">
    <visual>
      <geometry>
        <mesh filename="file:///home/users/aleix.ripoll/robotFIK_ws/src/robotfik/urdf/UR5_DAE/visual/Wrist3.dae"/>
      </geometry>
    </visual>
    <collision>
      <material name="grey"/>
      <origin xyz="0 0.0784 0" rpy="1.570796325 0 0"/>
      <geometry>
         <cylinder radius="0.0319" length="0.007"/>
      </geometry>
    </collision>
    <inertial>
      <mass value="0.1879"/>
      <inertia ixx="0.0171364731454" ixy="0" ixz="0" iyy="0.0171364731454" iyz="0" izz="0.033822"/>
    </inertial>
  </link>
  <joint name="SupportJoint_L" type="fixed">
    <parent link="Wrist3_L"/>
    <child link="Support_L"/>
    <origin rpy="-1.570796325 0 0" xyz="0 0.0983 0"/>
  </joint>
  <link name="Support_L">
    <visual>
      <geometry>
        <mesh filename="file:///home/users/aleix.ripoll/robotFIK_ws/src/robotfik/urdf/UR5_DAE/visual/AH_support.dae" scale="0.001 0.001 0.001"/>
      </geometry>
    </visual>
    <collision>
      <material name="grey"/>
      <origin rpy="0 0 1.570796327"/>
      <geometry>
         <cylinder radius="0.0355" length="0.032"/>
      </geometry>
    </collision>
  </link>
  <joint name="PalmJoint_L" type="fixed">
    <parent link="Support_L"/>
    <child link="Palm_L"/>
    <origin rpy="0 0 1.570796327" xyz="0 0.009 0.111"/>
  </joint>
  <link name="Palm_L">
    <visual>
      <geometry>
	<mesh filename="file:///home/users/aleix.ripoll/robotFIK_ws/src/robotfik/urdf/AllegroHand/left/base_link_left.dae" scale="0.001 0.001 0.001"/>
      </geometry>
    </visual>
    <collision>
      <material name="black"/>
	<origin xyz="-0.009300 0 -0.0475"/>
	<geometry>
	  <box size="0.0408 0.1130 0.095"/>
	</geometry>
    </collision>
  </link>
  <link name="Ring-base_L">
    <visual>
      <geometry>
        <mesh filename="file:///home/users/aleix.ripoll/robotFIK_ws/src/robotfik/urdf/AllegroHand/left/link_0_0.dae" scale="0.001 0.001 0.001"/>
      </geometry>
      <origin xyz="0 0 0.0164"/>
    </visual>
    <collision>
      <material name="black"/>
      <geometry>
        <box size="0.0196 0.0275 0.0164"/>
      </geometry>
      <origin xyz="0 0 0.0082"/>
    </collision>
  </link>
  <joint name="joint_8.0_L" type="revolute">
      <axis xyz="0 0 1"/>
      <limit effort="1" lower="-0.47" upper="0.47" velocity="1"/>
      <parent link="Palm_L"/>
      <child link="Ring-base_L"/>
      <origin rpy="-0.08726646255 0 0" xyz="0 0.0435 -0.001542"/>
  </joint>
  <link name="Ring-proximal_L">
    <visual>
      <geometry>
        <mesh filename="file:///home/users/aleix.ripoll/robotFIK_ws/src/robotfik/urdf/AllegroHand/left/link_1_0.dae" scale="0.001 0.001 0.001"/>
      </geometry>
      <origin rpy="1.5707963 -1.5707963 0"/>
    </visual>
    <collision>
      <material name="black"/>
      <geometry>
        <box size="0.0196 0.0275 0.054"/>
      </geometry>
      <origin xyz="0 0 0.027"/>
    </collision>
  </link>
  <joint name="joint_9.0_L" type="revolute">
      <limit effort="1" lower="-0.196" upper="1.61" velocity="1"/>
      <axis xyz="0 1 0"/>
      <parent link="Ring-base_L"/>
      <child link="Ring-proximal_L"/>
      <origin xyz="0 0 0.0164"/>
  </joint>
  <link name="Ring-distal_L">
    <visual>
      <geometry>
        <mesh filename="file:///home/users/aleix.ripoll/robotFIK_ws/src/robotfik/urdf/AllegroHand/left/link_2_0.dae" scale="0.001 0.001 0.001"/>
      </geometry>
      <origin rpy="-1.5707963 -1.5707963 0"/>
    </visual>
    <collision>
      <material name="black"/>
      <geometry>
        <box size="0.0196 0.0275 0.0384"/>
      </geometry>
      <origin xyz="0 0 0.0192"/>
    </collision>
  </link>
  <joint name="joint_10.0_L" type="revolute">
      <axis xyz="0 1 0"/>
      <limit effort="1" lower="-0.174" upper="1.709" velocity="1"/>
      <parent link="Ring-proximal_L"/>
      <child link="Ring-distal_L"/>
      <origin xyz="0 0 0.054"/>
  </joint>
  <link name="Ring-last_L">
    <visual>
      <geometry>
        <mesh filename="file:///home/users/aleix.ripoll/robotFIK_ws/src/robotfik/urdf/AllegroHand/left/link_3_0.dae" scale="0.001 0.001 0.001"/>
      </geometry>
      <origin rpy="-1.5707963 -1.5707963 0"/>
    </visual>
    <collision>
      <material name="black"/>
      <geometry>
        <box size="0.0196 0.0275 0.0267"/>
      </geometry>
      <origin xyz="0 0 0.01335"/>
    </collision>
  </link>
  <joint name="joint_11.0_L" type="revolute">
      <axis xyz="0 1 0"/>
      <limit effort="1" lower="-0.227" upper="1.618" velocity="1"/>
      <parent link="Ring-distal_L"/>
      <child link="Ring-last_L"/>
      <origin xyz="0 0 0.0384"/>
  </joint>
  <link name="link_11_0_tip_L">
    <visual>
      <geometry>
        <mesh filename="file:///home/users/aleix.ripoll/robotFIK_ws/src/robotfik/urdf/AllegroHand/left/sensing_tip.dae" scale="0.001 0.001 0.001"/>
      </geometry>
      <origin rpy="1.5707963 0 1.5707963" xyz="0.0038 0 0.0142"/>
    </visual>
    <collision>
      <material name="white">
        <color rgba="1 1 1 1"/>
      </material>
      <geometry>
        <box size="0.019 0.023 0.0365"/>
      </geometry>
      <origin xyz="0.0043 0 0.0125"/>
    </collision>
  </link>
  <joint name="joint_11_0_tip_L" type="fixed">
      <parent link="Ring-last_L"/>
      <child link="link_11_0_tip_L"/>
      <origin xyz="0 0 0.0267"/>
  </joint>
  <link name="Medium-base_L">
    <visual>
      <geometry>
        <mesh filename="file:///home/users/aleix.ripoll/robotFIK_ws/src/robotfik/urdf/AllegroHand/left/link_0_0.dae" scale="0.001 0.001 0.001"/>
      </geometry>
      <origin xyz="0 0 0.0164"/>
    </visual>
    <collision>
      <material name="black"/>
      <geometry>
        <box size="0.0196 0.0275 0.0164"/>
      </geometry>
      <origin xyz="0 0 0.0082"/>
    </collision>
  </link>
  <joint name="joint_4.0_L" type="revolute">
      <axis xyz="0 0 1"/>
      <limit effort="1" lower="-0.47" upper="0.47" velocity="1"/>
      <parent link="Palm_L"/>
      <child link="Medium-base_L"/>
      <origin xyz="0 0 0.0007"/>
  </joint>
  <link name="Medium-proximal_L">
    <visual>
      <geometry>
        <mesh filename="file:///home/users/aleix.ripoll/robotFIK_ws/src/robotfik/urdf/AllegroHand/left/link_1_0.dae" scale="0.001 0.001 0.001"/>
      </geometry>
      <origin rpy="1.5707963 -1.5707963 0"/>
    </visual>
    <collision>
      <material name="black"/>
      <geometry>
        <box size="0.0196 0.0275 0.054"/>
      </geometry>
      <origin xyz="0 0 0.027"/>
    </collision>
  </link>
  <joint name="joint_5.0_L" type="revolute">
      <limit effort="1" lower="-0.196" upper="1.61" velocity="1"/>
      <axis xyz="0 1 0"/>
      <parent link="Medium-base_L"/>
      <child link="Medium-proximal_L"/>
      <origin xyz="0 0 0.0164"/>
  </joint>
  <link name="Medium-distal_L">
    <visual>
      <geometry>
        <mesh filename="file:///home/users/aleix.ripoll/robotFIK_ws/src/robotfik/urdf/AllegroHand/left/link_2_0.dae" scale="0.001 0.001 0.001"/>
      </geometry>
      <origin rpy="-1.5707963 -1.5707963 0"/>
    </visual>
    <collision>
      <material name="black"/>
      <geometry>
        <box size="0.0196 0.0275 0.0384"/>
      </geometry>
      <origin xyz="0 0 0.0192"/>
    </collision>
  </link>
  <joint name="joint_6.0_L" type="revolute">
      <axis xyz="0 1 0"/>
      <limit effort="1" lower="-0.174" upper="1.709" velocity="1"/>
      <parent link="Medium-proximal_L"/>
      <child link="Medium-distal_L"/>
      <origin xyz="0 0 0.054"/>
  </joint>
  <link name="Medium-last_L">
    <visual>
      <geometry>
        <mesh filename="file:///home/users/aleix.ripoll/robotFIK_ws/src/robotfik/urdf/AllegroHand/left/link_3_0.dae" scale="0.001 0.001 0.001"/>
      </geometry>
      <origin rpy="-1.5707963 -1.5707963 0"/>
    </visual>
    <collision>
      <material name="black"/>
      <geometry>
        <box size="0.0196 0.0275 0.0267"/>
      </geometry>
      <origin xyz="0 0 0.01335"/>
    </collision>
  </link>
  <joint name="joint_7.0_L" type="revolute">
      <axis xyz="0 1 0"/>
      <limit effort="1" lower="-0.227" upper="1.618" velocity="1"/>
      <parent link="Medium-distal_L"/>
      <child link="Medium-last_L"/>
      <origin xyz="0 0 0.0384"/>
  </joint>
  <link name="link_7_0_tip_L">
    <visual>
      <geometry>
        <mesh filename="file:///home/users/aleix.ripoll/robotFIK_ws/src/robotfik/urdf/AllegroHand/left/sensing_tip.dae" scale="0.001 0.001 0.001"/>
      </geometry>
      <origin rpy="1.5707963 0 1.5707963" xyz="0.0038 0 0.0142"/>
    </visual>
    <collision>
      <material name="white"/>
      <geometry>
        <box size="0.019 0.023 0.0365"/>
      </geometry>
      <origin xyz="0.0043 0 0.0125"/>
    </collision>
  </link>
  <joint name="joint_7_0_tip_L" type="fixed">
      <parent link="Medium-last_L"/>
      <child link="link_7_0_tip_L"/>
      <origin xyz="0 0 0.0267"/>
  </joint>
  <link name="Index-base_L">
    <visual>
      <geometry>
        <mesh filename="file:///home/users/aleix.ripoll/robotFIK_ws/src/robotfik/urdf/AllegroHand/left/link_0_0.dae" scale="0.001 0.001 0.001"/> 
      </geometry>
      <origin xyz="0 0 0.0164"/>
    </visual>
    <collision>
      <material name="black"/>
      <geometry>
        <box size="0.0196 0.0275 0.0164"/>
      </geometry>
      <origin xyz="0 0 0.0082"/>
    </collision>
  </link>
  <joint name="joint_0.0_L" type="revolute">
      <axis xyz="0 0 1"/>
      <limit effort="1" lower="-0.47" upper="0.47" velocity="1"/>
      <parent link="Palm_L"/>
      <child link="Index-base_L"/>
      <origin rpy="0.08726646255 0 0" xyz="0 -0.0435 -0.001542"/>
  </joint>
  <link name="Index-proximal_L">
    <visual>
      <geometry>
        <mesh filename="file:///home/users/aleix.ripoll/robotFIK_ws/src/robotfik/urdf/AllegroHand/left/link_1_0.dae" scale="0.001 0.001 0.001"/>
      </geometry>
      <origin rpy="1.5707963 -1.5707963 0"/>
    </visual>
    <collision>
      <material name="black"/>
      <geometry>
        <box size="0.0196 0.0275 0.054"/>
      </geometry>
      <origin xyz="0 0 0.027"/>
    </collision>
  </link>
  <joint name="joint_1.0_L" type="revolute">
      <limit effort="1" lower="-0.196" upper="1.61" velocity="1"/>
      <axis xyz="0 1 0"/>
      <parent link="Index-base_L"/>
      <child link="Index-proximal_L"/>
      <origin xyz="0 0 0.0164"/>
  </joint>
  <link name="Index-distal_L">
    <visual>
      <geometry>
        <mesh filename="file:///home/users/aleix.ripoll/robotFIK_ws/src/robotfik/urdf/AllegroHand/left/link_2_0.dae" scale="0.001 0.001 0.001"/>
      </geometry>
      <origin rpy="-1.5707963 -1.5707963 0"/>
    </visual>
    <collision>
      <material name="black"/>
      <geometry>
        <box size="0.0196 0.0275 0.0384"/>
      </geometry>
      <origin xyz="0 0 0.0192"/>
    </collision>
  </link>
  <joint name="joint_2.0_L" type="revolute">
      <axis xyz="0 1 0"/>
      <limit effort="1" lower="-0.174" upper="1.709" velocity="1"/>
      <parent link="Index-proximal_L"/>
      <child link="Index-distal_L"/>
      <origin xyz="0 0 0.054"/>
  </joint>
  <link name="Index-last_L">
    <visual>
      <geometry>
        <mesh filename="file:///home/users/aleix.ripoll/robotFIK_ws/src/robotfik/urdf/AllegroHand/left/link_3_0.dae" scale="0.001 0.001 0.001"/>
      </geometry>
      <origin rpy="-1.5707963 -1.5707963 0"/>
    </visual>
    <collision>
      <material name="black"/>
      <geometry>
        <box size="0.0196 0.0275 0.0267"/>
      </geometry>
      <origin xyz="0 0 0.01335"/>
    </collision>
  </link>
  <joint name="joint_3.0_L" type="revolute">
      <axis xyz="0 1 0"/>
      <limit effort="1" lower="-0.227" upper="1.618" velocity="1"/>
      <parent link="Index-distal_L"/>
      <child link="Index-last_L"/>
      <origin xyz="0 0 0.0384"/>
  </joint>
  <link name="link_3_0_tip_L">
    <visual>
      <geometry>
        <mesh filename="file:///home/users/aleix.ripoll/robotFIK_ws/src/robotfik/urdf/AllegroHand/left/sensing_tip.dae" scale="0.001 0.001 0.001"/>
      </geometry>
      <origin rpy="1.5707963 0 1.5707963" xyz="0.0038 0 0.0142"/>
    </visual>
    <collision>
      <material name="white"/>
      <geometry>
        <box size="0.019 0.023 0.0365"/>
      </geometry>
      <origin xyz="0.0043 0 0.0125"/>
    </collision>
  </link>
  <joint name="joint_3_0_tip_L" type="fixed">
      <parent link="Index-last_L"/>
      <child link="link_3_0_tip_L"/>
      <origin xyz="0 0 0.0267"/>
  </joint>
  <link name="Thumb-base_L">
    <visual>
      <geometry>
        <mesh filename="file:///home/users/aleix.ripoll/robotFIK_ws/src/robotfik/urdf/AllegroHand/left/link_12_0_left.dae" scale="0.001 0.001 0.001"/>
      </geometry>
      <origin rpy="-1.570796327 0 -1.570796327" xyz="-0.02775 0 0"/>
    </visual>
    <collision>
      <material name="black"/>
      <geometry>
        <box size="0.0358 0.034 0.0455"/>
      </geometry>
      <origin xyz="-0.0179 0.009 0.0145"/>
    </collision>
  </link>
  <joint name="joint_12.0_L" type="revolute">
      <axis xyz="1 0 0"/>
      <limit effort="1" lower="0.263" upper="1.396" velocity="1"/>
      <parent link="Palm_L"/>
      <child link="Thumb-base_L"/>
    <origin rpy="0 -1.65806278845 1.5707963259" xyz="-0.0182 -0.019333 -0.045987"/>
  </joint>
  <link name="Thumb-proximal_L">
    <visual>
      <geometry>
        <mesh filename="file:///home/users/aleix.ripoll/robotFIK_ws/src/robotfik/urdf/AllegroHand/left/link_13_0.dae" scale="0.001 0.001 0.001"/>
      </geometry>
      <origin xyz="0 0 0.016000001" rpy="3.141592654 0 3.141592654"/>
    </visual>
    <collision>
      <material name="black"/>
      <geometry>
        <box size="0.0196 0.0275 0.0177"/>
      </geometry>
      <origin xyz="0 0 0.00885"/>
    </collision>
  </link>
  <joint name="joint_13.0_L" type="revolute">
      <axis xyz="0 0 -1"/>
      <limit effort="1" lower="-0.105" upper="1.163" velocity="1"/>
      <parent link="Thumb-base_L"/>
      <child link="Thumb-proximal_L"/>
      <origin xyz="-0.027 0.005 0.0399"/>
  </joint>
  <link name="Thumb-distal_L">
    <visual>
      <geometry>
        <mesh filename="file:///home/users/aleix.ripoll/robotFIK_ws/src/robotfik/urdf/AllegroHand/left/link_14_0.dae" scale="0.001 0.001 0.001"/>
      </geometry>
      <origin rpy="-1.5707963259 -1.5707963259 0"/>
    </visual>
    <collision>
      <material name="black"/>
      <geometry>
        <box size="0.0196 0.0275 0.0514"/>
      </geometry>
      <origin xyz="0 0 0.0257"/>
    </collision>
  </link>
  <joint name="joint_14.0_L" type="revolute">
      <axis xyz="0 1 0"/>
      <limit effort="1" lower="-0.189" upper="1.644" velocity="1"/>
      <parent link="Thumb-proximal_L"/>
      <child link="Thumb-distal_L"/>
      <origin xyz="0 0 0.0177"/>
  </joint>
  <link name="Thumb-last_L">
    <visual>
      <geometry>
        <mesh filename="file:///home/users/aleix.ripoll/robotFIK_ws/src/robotfik/urdf/AllegroHand/left/link_15_0.dae" scale="0.001 0.001 0.001"/>
      </geometry>
      <origin rpy="1.5707963259 -1.5707963259 0"/>
    </visual>
    <collision>
      <material name="black"/>
      <geometry>
        <box size="0.0196 0.0275 0.0423"/>
      </geometry>
      <origin xyz="0 0 0.02115"/>
    </collision>
  </link>
  <joint name="joint_15.0_L" type="revolute">
      <axis xyz="0 1 0"/>
      <limit effort="1" lower="-0.162" upper="1.719" velocity="1"/>
      <parent link="Thumb-distal_L"/>
      <child link="Thumb-last_L"/>
      <origin xyz="0 0 0.0514"/>
  </joint>
  <link name="link_15_0_tip_L">
    <visual>
      <geometry>
        <mesh filename="file:///home/users/aleix.ripoll/robotFIK_ws/src/robotfik/urdf/AllegroHand/right/sensing_tip.dae" scale="0.001 0.001 0.001"/>
      </geometry>
      <origin rpy="1.5707963 0 1.5707963" xyz="0.0038 0 0.0142"/>
    </visual>
    <collision>
      <material name="white"/>
      <geometry>
        <box size="0.019 0.023 0.0365"/>
      </geometry>
      <origin xyz="0.0043 0 0.0125"/>
    </collision>
  </link>
  <joint name="joint_15_0_tip_L" type="fixed">
      <parent link="Thumb-last_L"/>
      <child link="link_15_0_tip_L"/>
      <origin xyz="0 0 0.0423"/>
  </joint>
  
  </robot>

